Workbook

Sheet M1
A1: 关卡格子数越多，单装备DPS越低 | H1: 最终DPS倍率 | J1: 最终HP倍率 | M1: 保底灵石 | N1: 对标关卡 | Q1: 保底元宝 | R1: 对标关卡 | S1: 保底碎片元宝价值
A2: 过关标准：平均抵达X级的装备，即可过关 | H2: 32 | J2: 32 | M2: ='关卡表|pass'!AB55 -> 16912.5 | N2: 50 | Q2: ='关卡表|pass'!AA55 -> 29500 | R2: 50 | S2: =Q2 -> 29500
A3: 敌人标准：最大出怪HP之和，可以在怪物开火时全灭 | M3: 双倍后保底 | Q3: 双倍后保底
G4: 最终DPS | H4: 总和 | I4: 武器倍率 | J4: 天赋倍率 | M4: =M2*2 -> 33825 | Q4: =(Q2+T2)*2 -> 59000
G5: =H2*B8 -> 320 | H5: =I5*B8*(J5+1) -> 320 | I5: 10 | J5: 2.2 | M5: 额外广告标准收入 | Q5: 额外广告标准收入
A6: 标准武器DPS | M6: 500 | Q6: 1000
A7: 等级 | B7: 期望DPS | C7: 要求 | D7: 比值 | H7: HP比例 | M7: 总广告需求 | N7: 保底倍率需求 | Q7: 总广告需求 | R7: 保底倍率需求
A8: 1 | B8: 10 | C8: 严格 | D8: 1 | H8: 0.5 | M8: 1000 | N8: 50 | Q8: 1000 | R8: 50
A9: 2 | B9: 20 | C9: 严格 | D9: =B9/$B$8 -> 2
A10: 3 | B10: 30 | C10: 宽松 | D10: =B10/$B$8 -> 3 | H10: 初始HP | I10: 最终HP | J10: 最终护盾 | M10: 总需求 | Q10: 总需求
A11: 4 | B11: 40 | C11: 最宽松 | D11: =B11/$B$8 -> 4 | H11: ='英雄|hero'!E5 -> 100 | I11: =(H11*J2-H11)*H8+H11 -> 1650 | J11: =H11*J2-I11 -> 1550 | M11: =M2*N8+M6*M8 -> 1345625 | Q11: =(Q2+S2)*R8+Q6*Q8 -> 3950000
N12: 占比 | O12: 值 | R12: 占比 | S12: 值
H13: 总和 | I13: 天赋HP | M13: 保留 | N13: =100-N14-N15 -> 0 | O13: =INT(M11*N13/100) -> 0 | Q13: 保留 | R13: =100-R14-R15 -> 0 | S13: =INT(Q11*R13/100) -> 0
A14: 标准关卡格子数 | C14: 小怪标准DPS | H14: =(I14)*H11+H11 -> 1600 | I14: 15 | M14: 天赋升级 | N14: 100 | O14: =INT($M$11*N14/100) -> 1345625 | Q14: 装备升级 | R14: 35 | S14: =INT($Q$11*R14/100) -> 1382500
A15: 9 | C15: 0.3 | H15: 总和 | I15: 天赋SP | O15: =INT($M$11*N15/100) -> 0 | Q15: 碎片花费 | R15: 65 | S15: =INT($Q$11*R15/100) -> 2567500
A16: 标准触发间隔 | C16: BOSS攻击倍率 | H16: =(I16)*H11 -> 1600 | I16: 16
A17: 1 | B17: 秒 | C17: 1
A18: 过关标准：平均抵达
A19: 3 | B19: 级 | G19: 颜色 | H19: 总碎片需求
A20: 实际标准DPS | G20: 1 | H20: 1000 | M20: 雪的新娘配置
A21: =VLOOKUP(A19,A8:B11,2,FALSE)*A15/A17 -> 270 | G21: 2 | H21: 1000 | N21: 毒期望时间 | O21: 对标天赋级 | P21: 标准HP | Q21: 秒伤 | R21: DOT间隔 | S21: 结果 | T21: 标准护盾 | U21: 抗怪数 | V21: 单怪伤害
A22: 怪物攻击等待 | G22: 3 | H22: 800 | M22: 1阶段 | N22: 90 | O22: 55 | P22: =VLOOKUP(O22,'天赋|talent'!$P$5:$AH$512,19,FALSE)+$H$11 -> 752 | Q22: =P22/N22 -> 8.3555556 | R22: ='BUFF|buff'!M50/1000 -> 1 | S22: ="["&INT(Q22*R22)&","&ROUNDUP(Q22*R22,0)&"]" -> [8,9] | T22: =P22 -> 752 | U22: 999 | V22: =ROUNDUP(T22/U22,0) -> 1
A23: 5 | B23: 秒 | G23: 4 | H23: 600 | M23: 2阶段 | N23: 90 | O23: 55 | P23: =VLOOKUP(O23,'天赋|talent'!$P$5:$AH$512,19,FALSE)+$H$11 -> 752 | Q23: =P23/N23 -> 8.3555556 | R23: ='BUFF|buff'!M51/1000 -> 1.66 | S23: ="["&INT(Q23*R23)&","&ROUNDUP(Q23*R23,0)&"]" -> [13,14] | T23: =P23 -> 752 | U23: 500 | V23: =ROUNDUP(T23/U23,0) -> 2
A24: 怪物总HP | G24: 5 | H24: 400 | M24: 3阶段 | N24: 90 | O24: 55 | P24: =VLOOKUP(O24,'天赋|talent'!$P$5:$AH$512,19,FALSE)+$H$11 -> 752 | Q24: =P24/N24 -> 8.3555556 | R24: ='BUFF|buff'!M52/1000 -> 1.33 | S24: ="["&INT(Q24*R24)&","&ROUNDUP(Q24*R24,0)&"]" -> [11,12] | T24: =P24 -> 752 | U24: 333 | V24: =ROUNDUP(T24/U24,0) -> 3
A25: =A21*A23 -> 1350 | M25: 4阶段 | N25: 90 | O25: 100 | P25: =VLOOKUP(O25,'天赋|talent'!$P$5:$AH$512,19,FALSE)+$H$11 -> 1373 | Q25: =P25/N25 -> 15.255556 | R25: ='BUFF|buff'!M53/1000 -> 1 | S25: ="["&INT(Q25*R25)&","&ROUNDUP(Q25*R25,0)&"]" -> [15,16] | T25: =P25 -> 1373 | U25: 444 | V25: =ROUNDUP(T25/U25,0) -> 4
A26: 一波怪标准数量
A27: 100
A28: 小怪单HP
A29: =A25/A27 -> 13.5
A32: 每小时产出 | B32: 元宝算法 | C32: 灵石算法
A33: 基础 | B33: 20 | C33: 10
A34: 每关加 | B34: 4 | C34: 2.5
F35: 总权重 | G35: 平均每碎片标准抽价值
F36: =SUM(F38:F54)+F56 -> 1871 | G36: =SUM(J38:J54)+J56 -> 217.58475
A37: 对应装备大类ID | B37: 道具 | C37: 元宝价值 | D37: 灵石价值 | E37: 碎片消耗需求 | F37: 装备升级养成占比 | G37: 颜色 | H37: 升级元宝消耗 | I37: 标准掉落权重
A38: 1 | B38: 道法箭碎片 | C38: =$S$15/E38*(F38/$F$36) -> 83.70791 | D38: =C38/2 -> 41.853955 | E38: =VLOOKUP(G38,$G$20:$H$24,2,FALSE) -> 1000 | F38: 61 | G38: ='装备大类|wapenTable'!Z5 -> 2 | H38: =$S$14*(F38/$F$36) -> 45073.49 | I38: =E38 -> 1000 | J38: =I38/SUM($I$38:$I$54)*C38 -> 7.0938907
A39: 2 | B39: 鬼剑术碎片 | C39: =$S$15/E39*(F39/$F$36) -> 85.080171 | D39: =C39/2 -> 42.540086 | E39: =VLOOKUP(G39,$G$20:$H$24,2,FALSE) -> 1000 | F39: 62 | G39: ='装备大类|wapenTable'!Z6 -> 2 | H39: =$S$14*(F39/$F$36) -> 45812.4 | I39: =E39 -> 1000 | J39: =I39/SUM($I$38:$I$54)*C39 -> 7.210184
A40: 3 | B40: 降魔镖碎片 | C40: =$S$15/E40*(F40/$F$36) -> 86.452432 | D40: =C40/2 -> 43.226216 | E40: =VLOOKUP(G40,$G$20:$H$24,2,FALSE) -> 1000 | F40: 63 | G40: ='装备大类|wapenTable'!Z7 -> 2 | H40: =$S$14*(F40/$F$36) -> 46551.309 | I40: =E40 -> 1000 | J40: =I40/SUM($I$38:$I$54)*C40 -> 7.3264773
A41: 4 | B41: 摄魂符碎片 | C41: =$S$15/E41*(F41/$F$36) -> 87.824693 | D41: =C41/2 -> 43.912346 | E41: =VLOOKUP(G41,$G$20:$H$24,2,FALSE) -> 1000 | F41: 64 | G41: ='装备大类|wapenTable'!Z8 -> 2 | H41: =$S$14*(F41/$F$36) -> 47290.219 | I41: =E41 -> 1000 | J41: =I41/SUM($I$38:$I$54)*C41 -> 7.4427706
A42: 5 | B42: 打妖棍碎片 | C42: =$S$15/E42*(F42/$F$36) -> 154.37934 | D42: =C42/2 -> 77.189671 | E42: =VLOOKUP(G42,$G$20:$H$24,2,FALSE) -> 800 | F42: 90 | G42: ='装备大类|wapenTable'!Z9 -> 3 | H42: =$S$14*(F42/$F$36) -> 66501.871 | I42: =E42 -> 800 | J42: =I42/SUM($I$38:$I$54)*C42 -> 10.466396
...

Sheet M2
A1: 等级 | B1: 1 | C1: 2 | D1: 3 | E1: 4 | F1: 5 | G1: 6 | H1: 7 | I1: 8
A2: 1 | B2: 72 | C2: 108 | D2: 130 | E2: 156 | F2: 188 | G2: 190 | H2: 190 | M2: =B3/B2 -> 1.2361111
A3: 2 | B3: 89 | C3: 130 | D3: 195 | E3: 234 | F3: 301 | G3: 304 | H3: 323 | I3: 340 | R3: 怪物类型 | X3: 189 | Y3: 152
A4: 3 | B4: 108 | C4: 156 | D4: 293 | E4: 351 | F4: 482 | G4: 487 | H4: 550 | I4: 578 | Q4: 1 | R4: 2 | X4: 221 | Y4: 182
A5: 4 | B5: 130 | C5: 187 | D5: 439 | E5: 527 | F5: 771 | G5: 779 | H5: 934 | I5: 983 | Q5: 2 | R5: 2
A6: 5 | B6: 156 | C6: 224 | D6: 659 | E6: 790 | F6: 1233 | G6: 1246 | H6: 1587 | I6: 1671 | Q6: 3 | R6: 2 | S6: 1
A7: 6 | B7: 187 | C7: 269 | Q7: 4 | R7: 2
A8: 7 | B8: 224 | C8: 323 | Q8: 5 | R8: 2 | S8: 1
A9: 8 | B9: 269 | C9: 387 | Q9: 6 | R9: 2
A10: 9 | B10: 323 | C10: 465 | Q10: 7 | R10: 2 | S10: 3
A11: 10 | B11: 387 | C11: 558 | Q11: 8 | R11: 2
Q12: 9 | R12: 2
Q13: 10 | R13: 2 | S13: 1
A14: 1 | B14: =B3-B2 -> 17 | C14: =C3-C2 -> 22 | D14: =D3-D2 -> 65 | E14: =E3-E2 -> 78 | F14: =F3-F2 -> 113 | G14: =G3-G2 -> 114 | H14: =H3-H2 -> 133 | Q14: 11 | R14: 2
A15: 2 | B15: =B4-B3 -> 19 | C15: =C4-C3 -> 26 | D15: =D4-D3 -> 98 | E15: =E4-E3 -> 117 | F15: =F4-F3 -> 181 | G15: =G4-G3 -> 183 | H15: =H4-H3 -> 227 | Q15: 12 | R15: 2 | S15: 3
A16: 3 | B16: =B5-B4 -> 22 | C16: =C5-C4 -> 31 | D16: =D5-D4 -> 146 | E16: =E5-E4 -> 176 | F16: =F5-F4 -> 289 | G16: =G5-G4 -> 292 | H16: =H5-H4 -> 384 | Q16: 13 | R16: 2
A17: 4 | B17: =B6-B5 -> 26 | C17: =C6-C5 -> 37 | D17: =D6-D5 -> 220 | E17: =E6-E5 -> 263 | F17: =F6-F5 -> 462 | G17: =G6-G5 -> 467 | H17: =H6-H5 -> 653 | Q17: 14 | R17: 2 | S17: 1 | T17: 3
A18: 5 | B18: =B7-B6 -> 31 | C18: =C7-C6 -> 45 | Q18: 15 | R18: 2
A19: 6 | B19: =B8-B7 -> 37 | C19: =C8-C7 -> 54
A20: 7 | B20: =B9-B8 -> 45 | C20: =C9-C8 -> 64
A21: 8 | B21: =B10-B9 -> 54 | C21: =C10-C9 -> 78
A22: 9 | B22: =B11-B10 -> 64 | C22: =C11-C10 -> 93
A23: 10
A26: 1 | B26: =B15-B14 -> 2 | C26: =C15-C14 -> 4 | D26: =D15-D14 -> 33 | E26: =E15-E14 -> 39 | F26: =F15-F14 -> 68 | G26: =G15-G14 -> 69 | H26: =H15-H14 -> 94
A27: 2 | B27: =B16-B15 -> 3 | C27: =C16-C15 -> 5 | D27: =D16-D15 -> 48 | E27: =E16-E15 -> 59 | F27: =F16-F15 -> 108 | G27: =G16-G15 -> 109 | H27: =H16-H15 -> 157
A28: 3 | B28: =B17-B16 -> 4 | C28: =C17-C16 -> 6 | D28: =D17-D16 -> 74 | E28: =E17-E16 -> 87 | F28: =F17-F16 -> 173 | G28: =G17-G16 -> 175 | H28: =H17-H16 -> 269
A29: 4 | B29: =B18-B17 -> 5 | C29: =C18-C17 -> 8
A30: 5 | B30: =B19-B18 -> 6 | C30: =C19-C18 -> 9
A31: 6 | B31: =B20-B19 -> 8 | C31: =C20-C19 -> 10
A32: 7 | B32: =B21-B20 -> 9 | C32: =C21-C20 -> 14
A33: 8 | B33: =B22-B21 -> 10 | C33: =C22-C21 -> 15
A34: 9
A35: 10
B85: 获得宝物
A107: 横版三消+养成
A108: 1个英雄，加众多召唤角色，打群架
J162: 题材：打UFO，黑白简笔手绘风（类似火柴人大战）
J164: 玩法 | K164: 格子塔防的衍生规则
K165: 我方有1旗舰，带着舰队出战
K166: 舰队里的飞船通过金币购买上场
...

Sheet 道具表|itemBase
A1: ID | B1: 名字 | C1: 道具类型 | D1: 参数 | E1: 投放类型 | F1: ICON | G1: 背景颜色 | H1: 道具描述 | I1: 元宝价格 | J1: 灵石价格
A2: int | B2: string | C2: int | D2: int | E2: int | F2: string | G2: int | H2: string | I2: int | J2: int
A3: id | B3: name | C3: type | D3: typeArgs | E3: putType | F3: img | G3: colour | H3: describe | I3: cost1 | J3: cost2
A4: server/client | B4: server/client | C4: server/client | D4: server/client | E4: server/client | F4: server/client | G4: server/client | H4: server/client | I4: server/client | J4: server/client
A5: 1 | B5: 元宝 | C5: 0 | D5: 1 | F5: item_1 | G5: 1
A6: 2 | B6: 灵石 | C6: 0 | D6: 2 | F6: item_2 | G6: 2
A7: 3 | B7: 免广卷 | C7: 0 | D7: 3 | F7: item_3 | G7: 3
A8: 4 | B8: 铜钱 | C8: 0 | D8: 4 | F8: item_4 | G8: 1
A9: 5 | B9: 元宝 | C9: 0 | D9: 1 | E9: 1 | F9: item_1 | G9: 1
A10: 6 | B10: 灵石 | C10: 0 | D10: 2 | E10: 1 | F10: item_2 | G10: 2
A11: 7 | B11: =VLOOKUP(D11,'装备合成等级|wapenFusion'!$O$5:$P$1119,2,FALSE) -> 道法箭(1重) | C11: 1 | D11: 101
A12: 8 | B12: =VLOOKUP(D12,'装备合成等级|wapenFusion'!$O$5:$P$1119,2,FALSE) -> 道法箭(2重) | C12: 1 | D12: 102
A13: 9 | B13: =VLOOKUP(D13,'装备合成等级|wapenFusion'!$O$5:$P$1119,2,FALSE) -> 道法箭(3重) | C13: 1 | D13: 103
A14: 10 | B14: =VLOOKUP(D14,'装备合成等级|wapenFusion'!$O$5:$P$1119,2,FALSE) -> 道法箭(4重) | C14: 1 | D14: 104
A15: 11 | B15: =VLOOKUP(D15,'装备合成等级|wapenFusion'!$O$5:$P$1119,2,FALSE) -> 鬼剑术(1重) | C15: 1 | D15: =D11+100 -> 201
A16: 12 | B16: =VLOOKUP(D16,'装备合成等级|wapenFusion'!$O$5:$P$1119,2,FALSE) -> 鬼剑术(2重) | C16: 1 | D16: =D12+100 -> 202
A17: 13 | B17: =VLOOKUP(D17,'装备合成等级|wapenFusion'!$O$5:$P$1119,2,FALSE) -> 鬼剑术(3重) | C17: 1 | D17: =D13+100 -> 203
A18: 14 | B18: =VLOOKUP(D18,'装备合成等级|wapenFusion'!$O$5:$P$1119,2,FALSE) -> 鬼剑术(4重) | C18: 1 | D18: =D14+100 -> 204
A19: 15 | B19: =VLOOKUP(D19,'装备合成等级|wapenFusion'!$O$5:$P$1119,2,FALSE) -> 降魔镖(1重) | C19: 1 | D19: =D15+100 -> 301
A20: 16 | B20: =VLOOKUP(D20,'装备合成等级|wapenFusion'!$O$5:$P$1119,2,FALSE) -> 降魔镖(2重) | C20: 1 | D20: =D16+100 -> 302
A21: 17 | B21: =VLOOKUP(D21,'装备合成等级|wapenFusion'!$O$5:$P$1119,2,FALSE) -> 降魔镖(3重) | C21: 1 | D21: =D17+100 -> 303
A22: 18 | B22: =VLOOKUP(D22,'装备合成等级|wapenFusion'!$O$5:$P$1119,2,FALSE) -> 降魔镖(4重) | C22: 1 | D22: =D18+100 -> 304
A23: 19 | B23: =VLOOKUP(D23,'装备合成等级|wapenFusion'!$O$5:$P$1119,2,FALSE) -> 摄魂符(1重) | C23: 1 | D23: =D19+100 -> 401
A24: 20 | B24: =VLOOKUP(D24,'装备合成等级|wapenFusion'!$O$5:$P$1119,2,FALSE) -> 摄魂符(2重) | C24: 1 | D24: =D20+100 -> 402
A25: 21 | B25: =VLOOKUP(D25,'装备合成等级|wapenFusion'!$O$5:$P$1119,2,FALSE) -> 摄魂符(3重) | C25: 1 | D25: =D21+100 -> 403
A26: 22 | B26: =VLOOKUP(D26,'装备合成等级|wapenFusion'!$O$5:$P$1119,2,FALSE) -> 摄魂符(4重) | C26: 1 | D26: =D22+100 -> 404
... A53: 49 | B53: =VLOOKUP(D53,'装备合成等级|wapenFusion'!$O$5:$P$1119,2,FALSE) -> 定身咒(3重) | C53: 1 | D53: =D49+100 -> 1103
A54: 50 | B54: =VLOOKUP(D54,'装备合成等级|wapenFusion'!$O$5:$P$1119,2,FALSE) -> 定身咒(4重) | C54: 1 | D54: 1104
A55: 51 | B55: =VLOOKUP(D55,'装备合成等级|wapenFusion'!$O$5:$P$1119,2,FALSE) -> 击退(4重) | C55: 1 | D55: =D51+100 -> 1201
A56: 52 | B56: =VLOOKUP(D56,'装备合成等级|wapenFusion'!$O$5:$P$1119,2,FALSE) -> 击退(2重) | C56: 1 | D56: =D52+100 -> 1202
A57: 53 | B57: =VLOOKUP(D57,'装备合成等级|wapenFusion'!$O$5:$P$1119,2,FALSE) -> 击退(3重) | C57: 1 | D57: =D53+100 -> 1203
A58: 54 | B58: =VLOOKUP(D58,'装备合成等级|wapenFusion'!$O$5:$P$1119,2,FALSE) -> 击退(4重) | C58: 1 | D58: =D54+100 -> 1204
A59: 55 | B59: =VLOOKUP(D59,'装备合成等级|wapenFusion'!$O$5:$P$1119,2,FALSE) -> 生命(1重) | C59: 1 | D59: =D55+100 -> 1301
A60: 56 | B60: =VLOOKUP(D60,'装备合成等级|wapenFusion'!$O$5:$P$1119,2,FALSE) -> 生命(2重) | C60: 1 | D60: =D56+100 -> 1302
A61: 57 | B61: =VLOOKUP(D61,'装备合成等级|wapenFusion'!$O$5:$P$1119,2,FALSE) -> 生命(3重) | C61: 1 | D61: =D57+100 -> 1303
A62: 58 | B62: =VLOOKUP(D62,'装备合成等级|wapenFusion'!$O$5:$P$1119,2,FALSE) -> 生命(4重) | C62: 1 | D62: =D58+100 -> 1304
A63: 59 | B63: =VLOOKUP(D63,'装备合成等级|wapenFusion'!$O$5:$P$1119,2,FALSE) -> 护盾(1重) | C63: 1 | D63: =D59+100 -> 1401
A64: 60 | B64: =VLOOKUP(D64,'装备合成等级|wapenFusion'!$O$5:$P$1119,2,FALSE) -> 护盾(2重) | C64: 1 | D64: =D60+100 -> 1402
A65: 61 | B65: =VLOOKUP(D65,'装备合成等级|wapenFusion'!$O$5:$P$1119,2,FALSE) -> 护盾(3重) | C65: 1 | D65: =D61+100 -> 1403
A66: 62 | B66: =VLOOKUP(D66,'装备合成等级|wapenFusion'!$O$5:$P$1119,2,FALSE) -> 护盾(4重) | C66: 1 | D66: =D62+100 -> 1404
...

Sheet 抽奖-主库|drawMain
A1: 序号 | B1: 主库ID | C1: 子库ID | D1: 权重 | E1: 备注
A2: int | B2: int | C2: int | D2: int
A3: id | B3: mainDrawID | C3: subDrawID | D3: weight
A4: server/client | B4: server/client | C4: server/client | D4: server/client
A5: 1 | B5: 1 | C5: 1 | D5: 100
A6: =A5+1 -> 2 | B6: 2 | C6: 1 | D6: 70
A7: =A6+1 -> 3 | B7: 2 | C7: 2 | D7: 30
A8: =A7+1 -> 4 | B8: 3 | C8: 1 | D8: 50
A9: =A8+1 -> 5 | B9: 3 | C9: 2 | D9: 0
A10: =A9+1 -> 6 | B10: 3 | C10: 3 | D10: 50
A11: =A10+1 -> 7 | B11: 4 | C11: 4 | D11: 100
A12: =A11+1 -> 8 | B12: 5 | C12: 5 | D12: 100
A13: =A12+1 -> 9 | B13: 6 | C13: 6 | D13: 100
A14: =A13+1 -> 10 | B14: 7 | C14: 7 | D14: 100
A15: =A14+1 -> 11 | B15: 8 | C15: 8 | D15: 100
A16: =A15+1 -> 12 | B16: 9 | C16: 9 | D16: 100
A17: =A16+1 -> 13 | B17: 10 | C17: 10 | D17: 1
... A31: =A30+1 -> 27 | B31: 17 | C31: 18 | D31: 1
A32: =A31+1 -> 28 | B32: 18 | C32: 19 | D32: 1 | E32: 蓝装碎片
A33: =A32+1 -> 29 | B33: 19 | C33: 20 | D33: 1 | E33: 紫装碎片
A34: =A33+1 -> 30 | B34: 20 | C34: 21 | D34: 1 | E34: 黄装碎片
A35: =A34+1 -> 31 | B35: 21 | C35: 22 | D35: 1 | E35: 红装碎片
A36: =A35+1 -> 32 | B36: 22 | C36: 23 | D36: 1 | E36: 商店武器碎片
A37: =A36+1 -> 33 | B37: 23 | C37: 24 | D37: 1 | E37: 单一免广卷
A38: =A37+1 -> 34 | B38: 23 | C38: 23 | D38: 2 | E38: 商店武器碎片
A39: =A38+1 -> 35 | B39: 24 | C39: 25 | D39: 1 | E39: 产出任意1个武器碎片
A40: =A39+1 -> 36 | B40: 24 | C40: 17 | D40: 1 | E40: 什么都不出
A41: 36 | B41: 25 | C41: 25 | D41: 1
A42: 37 | B42: 26 | C42: 26 | D42: 1 | E42: BAN恢复，无武器
A43: 38 | B43: 26 | C43: 7 | D43: 1
A44: 39 | B44: 27 | C44: 27 | D44: 1 | E44: 1个元宝
A45: 40 | B45: 28 | C45: 28 | D45: 1 | E45: 1个灵石

Sheet 抽奖-子库|drawSub
G1: 道具颜色 | H1: 名字 | J1: 序号 | K1: 子库ID | L1: 道具ID | M1: 数量 | N1: 权重 | O1: 修正条件 | P1: 权重修正 | Q1: 广告概率 | R1: 道具类型
J2: int | K2: int | L2: int | M2: int | N2: int | O2: int[] | P2: double | Q2: int | R2: int
J3: id | K3: subDrawID | L3: itemId | M3: itemValue | N3: weight | O3: condition | P3: weight2 | Q3: adv | R3: type
H4: 道具名 | J4: server/client | K4: server/client | L4: server/client | M4: server/client | N4: server/client | O4: server/client | P4: server/client | Q4: server/client | R4: server/client
H5: =VLOOKUP(L5,'道具表|itemBase'!$A$5:$B$1112,2,FALSE) -> 道法箭(1重) | J5: 1 | K5: 1 | L5: 7 | M5: 1 | N5: 40 | Q5: 0 | R5: =VLOOKUP(L5,'道具表|itemBase'!$A$5:$C$1112,3,FALSE) -> 1
H6: =VLOOKUP(L6,'道具表|itemBase'!$A$5:$B$1112,2,FALSE) -> 道法箭(2重) | J6: =J5+1 -> 2 | K6: 1 | L6: 8 | M6: 1 | N6: 10 | O6: 2 | P6: 1.5 | Q6: 50 | R6: =VLOOKUP(L6,'道具表|itemBase'!$A$5:$C$1112,3,FALSE) -> 1
H7: =VLOOKUP(L7,'道具表|itemBase'!$A$5:$B$1112,2,FALSE) -> 道法箭(3重) | J7: =J6+1 -> 3 | K7: 1 | L7: 9 | M7: 1 | N7: 5 | O7: 2 | P7: 1.5 | Q7: 100 | R7: =VLOOKUP(L7,'道具表|itemBase'!$A$5:$C$1112,3,FALSE) -> 1
H8: =VLOOKUP(L8,'道具表|itemBase'!$A$5:$B$1112,2,FALSE) -> 道法箭(4重) | J8: =J7+1 -> 4 | K8: 1 | L8: 10 | M8: 1 | N8: 0 | Q8: 100 | R8: =VLOOKUP(L8,'道具表|itemBase'!$A$5:$C$1112,3,FALSE) -> 1
H9: =VLOOKUP(L9,'道具表|itemBase'!$A$5:$B$1112,2,FALSE) -> 鬼剑术(1重) | J9: =J8+1 -> 5 | K9: 1 | L9: 11 | M9: 1 | N9: =N5 -> 40 | Q9: 0 | R9: =VLOOKUP(L9,'道具表|itemBase'!$A$5:$C$1112,3,FALSE) -> 1
H10: =VLOOKUP(L10,'道具表|itemBase'!$A$5:$B$1112,2,FALSE) -> 鬼剑术(2重) | J10: =J9+1 -> 6 | K10: 1 | L10: 12 | M10: 1 | N10: =N6 -> 10 | O10: 2 | P10: 1.5 | Q10: 50 | R10: =VLOOKUP(L10,'道具表|itemBase'!$A$5:$C$1112,3,FALSE) -> 1
H11: =VLOOKUP(L11,'道具表|itemBase'!$A$5:$B$1112,2,FALSE) -> 鬼剑术(3重) | J11: =J10+1 -> 7 | K11: 1 | L11: 13 | M11: 1 | N11: =N7 -> 5 | O11: 2 | P11: 1.5 | Q11: 100 | R11: =VLOOKUP(L11,'道具表|itemBase'!$A$5:$C$1112,3,FALSE) -> 1
H12: =VLOOKUP(L12,'道具表|itemBase'!$A$5:$B$1112,2,FALSE) -> 鬼剑术(4重) | J12: =J11+1 -> 8 | K12: 1 | L12: 14 | M12: 1 | N12: =N8 -> 0 | Q12: 100 | R12: =VLOOKUP(L12,'道具表|itemBase'!$A$5:$C$1112,3,FALSE) -> 1
H13: =VLOOKUP(L13,'道具表|itemBase'!$A$5:$B$1112,2,FALSE) -> 降魔镖(1重) | J13: =J12+1 -> 9 | K13: 1 | L13: 15 | M13: 1 | N13: =N9 -> 40 | Q13: 0 | R13: =VLOOKUP(L13,'道具表|itemBase'!$A$5:$C$1112,3,FALSE) -> 1
H14: =VLOOKUP(L14,'道具表|itemBase'!$A$5:$B$1112,2,FALSE) -> 降魔镖(2重) | J14: =J13+1 -> 10 | K14: 1 | L14: 16 | M14: 1 | N14: =N10 -> 10 | O14: 2 | P14: 1.5 | Q14: 50 | R14: =VLOOKUP(L14,'道具表|itemBase'!$A$5:$C$1112,3,FALSE) -> 1
H15: =VLOOKUP(L15,'道具表|itemBase'!$A$5:$B$1112,2,FALSE) -> 降魔镖(3重) | J15: =J14+1 -> 11 | K15: 1 | L15: 17 | M15: 1 | N15: =N11 -> 5 | O15: 2 | P15: 1.5 | Q15: 100 | R15: =VLOOKUP(L15,'道具表|itemBase'!$A$5:$C$1112,3,FALSE) -> 1
H16: =VLOOKUP(L16,'道具表|itemBase'!$A$5:$B$1112,2,FALSE) -> 降魔镖(4重) | J16: =J15+1 -> 12 | K16: 1 | L16: 18 | M16: 1 | N16: =N12 -> 0 | Q16: 100 | R16: =VLOOKUP(L16,'道具表|itemBase'!$A$5:$C$1112,3,FALSE) -> 1
H17: =VLOOKUP(L17,'道具表|itemBase'!$A$5:$B$1112,2,FALSE) -> 摄魂符(1重) | J17: =J16+1 -> 13 | K17: 1 | L17: 19 | M17: 1 | N17: =N13 -> 40 | Q17: 0 | R17: =VLOOKUP(L17,'道具表|itemBase'!$A$5:$C$1112,3,FALSE) -> 1
H18: =VLOOKUP(L18,'道具表|itemBase'!$A$5:$B$1112,2,FALSE) -> 摄魂符(2重) | J18: =J17+1 -> 14 | K18: 1 | L18: 20 | M18: 1 | N18: =N14 -> 10 | O18: 2 | P18: 1.5 | Q18: 50 | R18: =VLOOKUP(L18,'道具表|itemBase'!$A$5:$C$1112,3,FALSE) -> 1
H19: =VLOOKUP(L19,'道具表|itemBase'!$A$5:$B$1112,2,FALSE) -> 摄魂符(3重) | J19: =J18+1 -> 15 | K19: 1 | L19: 21 | M19: 1 | N19: =N15 -> 5 | O19: 2 | P19: 1.5 | Q19: 100 | R19: =VLOOKUP(L19,'道具表|itemBase'!$A$5:$C$1112,3,FALSE) -> 1
H20: =VLOOKUP(L20,'道具表|itemBase'!$A$5:$B$1112,2,FALSE) -> 摄魂符(4重) | J20: =J19+1 -> 16 | K20: 1 | L20: 22 | M20: 1 | N20: =N16 -> 0 | Q20: 100 | R20: =VLOOKUP(L20,'道具表|itemBase'!$A$5:$C$1112,3,FALSE) -> 1
H21: =VLOOKUP(L21,'道具表|itemBase'!$A$5:$B$1112,2,FALSE) -> 打妖棍(1重) | J21: =J20+1 -> 17 | K21: 1 | L21: 23 | M21: 1 | N21: =N17 -> 40 | Q21: 0 | R21: =VLOOKUP(L21,'道具表|itemBase'!$A$5:$C$1112,3,FALSE) -> 1
H22: =VLOOKUP(L22,'道具表|itemBase'!$A$5:$B$1112,2,FALSE) -> 打妖棍(2重) | J22: =J21+1 -> 18 | K22: 1 | L22: 24 | M22: 1 | N22: =N18 -> 10 | O22: 2 | P22: 1.5 | Q22: 50 | R22: =VLOOKUP(L22,'道具表|itemBase'!$A$5:$C$1112,3,FALSE) -> 1
H23: =VLOOKUP(L23,'道具表|itemBase'!$A$5:$B$1112,2,FALSE) -> 打妖棍(3重) | J23: =J22+1 -> 19 | K23: 1 | L23: 25 | M23: 1 | N23: =N19 -> 5 | O23: 2 | P23: 1.5 | Q23: 100 | R23: =VLOOKUP(L23,'道具表|itemBase'!$A$5:$C$1112,3,FALSE) -> 1
H24: =VLOOKUP(L24,'道具表|itemBase'!$A$5:$B$1112,2,FALSE) -> 打妖棍(4重) | J24: =J23+1 -> 20 | K24: 1 | L24: 26 | M24: 1 | N24: =N20 -> 0 | Q24: 100 | R24: =VLOOKUP(L24,'道具表|itemBase'!$A$5:$C$1112,3,FALSE) -> 1
H25: =VLOOKUP(L25,'道具表|itemBase'!$A$5:$B$1112,2,FALSE) -> 旋风轮(1重) | J25: =J24+1 -> 21 | K25: 1 | L25: 27 | M25: 1 | N25: =N21 -> 40 | Q25: 0 | R25: =VLOOKUP(L25,'道具表|itemBase'!$A$5:$C$1112,3,FALSE) -> 1
H26: =VLOOKUP(L26,'道具表|itemBase'!$A$5:$B$1112,2,FALSE) -> 旋风轮(2重) | J26: =J25+1 -> 22 | K26: 1 | L26: 28 | M26: 1 | N26: =N22 -> 10 | O26: 2 | P26: 1.5 | Q26: 50 | R26: =VLOOKUP(L26,'道具表|itemBase'!$A$5:$C$1112,3,FALSE) -> 1
H27: =VLOOKUP(L27,'道具表|itemBase'!$A$5:$B$1112,2,FALSE) -> 旋风轮(3重) | J27: =J26+1 -> 23 | K27: 1 | L27: 29 | M27: 1 | N27: =N23 -> 5 | O27: 2 | P27: 1.5 | Q27: 100 | R27: =VLOOKUP(L27,'道具表|itemBase'!$A$5:$C$1112,3,FALSE) -> 1
H28: =VLOOKUP(L28,'道具表|itemBase'!$A$5:$B$1112,2,FALSE) -> 旋风轮(4重) | J28: =J27+1 -> 24 | K28: 1 | L28: 30 | M28: 1 | N28: =N24 -> 0 | Q28: 100 | R28: =VLOOKUP(L28,'道具表|itemBase'!$A$5:$C$1112,3,FALSE) -> 1
H29: =VLOOKUP(L29,'道具表|itemBase'!$A$5:$B$1112,2,FALSE) -> 灭魂火(1重) | J29: =J28+1 -> 25 | K29: 1 | L29: 31 | M29: 1 | N29: =N25 -> 40 | Q29: 0 | R29: =VLOOKUP(L29,'道具表|itemBase'!$A$5:$C$1112,3,FALSE) -> 1
H30: =VLOOKUP(L30,'道具表|itemBase'!$A$5:$B$1112,2,FALSE) -> 灭魂火(2重) | J30: =J29+1 -> 26 | K30: 1 | L30: 32 | M30: 1 | N30: =N26 -> 10 | O30: 2 | P30: 1.5 | Q30: 50 | R30: =VLOOKUP(L30,'道具表|itemBase'!$A$5:$C$1112,3,FALSE) -> 1
H31: =VLOOKUP(L31,'道具表|itemBase'!$A$5:$B$1112,2,FALSE) -> 灭魂火(3重) | J31: =J30+1 -> 27 | K31: 1 | L31: 33 | M31: 1 | N31: =N27 -> 5 | O31: 2 | P31: 1.5 | Q31: 100 | R31: =VLOOKUP(L31,'道具表|itemBase'!$A$5:$C$1112,3,FALSE) -> 1
H32: =VLOOKUP(L32,'道具表|itemBase'!$A$5:$B$1112,2,FALSE) -> 灭魂火(4重) | J32: =J31+1 -> 28 | K32: 1 | L32: 34 | M32: 1 | N32: =N28 -> 0 | Q32: 100 | R32: =VLOOKUP(L32,'道具表|itemBase'!$A$5:$C$1112,3,FALSE) -> 1
H33: =VLOOKUP(L33,'道具表|itemBase'!$A$5:$B$1112,2,FALSE) -> 囚天指(1重) | J33: =J32+1 -> 29 | K33: 1 | L33: 35 | M33: 1 | N33: 20 | Q33: 0 | R33: =VLOOKUP(L33,'道具表|itemBase'!$A$5:$C$1112,3,FALSE) -> 1
H34: =VLOOKUP(L34,'道具表|itemBase'!$A$5:$B$1112,2,FALSE) -> 囚天指(2重) | J34: =J33+1 -> 30 | K34: 1 | L34: 36 | M34: 1 | N34: 5 | O34: 2 | P34: 1.5 | Q34: 50 | R34: =VLOOKUP(L34,'道具表|itemBase'!$A$5:$C$1112,3,FALSE) -> 1
H35: =VLOOKUP(L35,'道具表|itemBase'!$A$5:$B$1112,2,FALSE) -> 囚天指(3重) | J35: =J34+1 -> 31 | K35: 1 | L35: 37 | M35: 1 | N35: =N31 -> 5 | O35: 2 | P35: 1.5 | Q35: 100 | R35: =VLOOKUP(L35,'道具表|itemBase'!$A$5:$C$1112,3,FALSE) -> 1
H36: =VLOOKUP(L36,'道具表|itemBase'!$A$5:$B$1112,2,FALSE) -> 囚天指(4重) | J36: =J35+1 -> 32 | K36: 1 | L36: 38 | M36: 1 | N36: =N32 -> 0 | Q36: 100 | R36: =VLOOKUP(L36,'道具表|itemBase'!$A$5:$C$1112,3,FALSE) -> 1
H37: =VLOOKUP(L37,'道具表|itemBase'!$A$5:$B$1112,2,FALSE) -> 雷鸣器(1重) | J37: =J36+1 -> 33 | K37: 1 | L37: 170 | M37: 1 | N37: 20 | Q37: 0 | R37: =VLOOKUP(L37,'道具表|itemBase'!$A$5:$C$1112,3,FALSE) -> 1
H38: =VLOOKUP(L38,'道具表|itemBase'!$A$5:$B$1112,2,FALSE) -> 雷鸣器(2重) | J38: =J37+1 -> 34 | K38: 1 | L38: 171 | M38: 1 | N38: 5 | O38: 2 | P38: 1.5 | Q38: 50 | R38: =VLOOKUP(L38,'道具表|itemBase'!$A$5:$C$1112,3,FALSE) -> 1
H39: =VLOOKUP(L39,'道具表|itemBase'!$A$5:$B$1112,2,FALSE) -> 雷鸣器(3重) | J39: =J38+1 -> 35 | K39: 1 | L39: 172 | M39: 1 | N39: =N35 -> 5 | O39: 2 | P39: 1.5 | Q39: 100 | R39: =VLOOKUP(L39,'道具表|itemBase'!$A$5:$C$1112,3,FALSE) -> 1
H40: =VLOOKUP(L40,'道具表|itemBase'!$A$5:$B$1112,2,FALSE) -> 雷鸣器(4重) | J40: =J39+1 -> 36 | K40: 1 | L40: 173 | M40: 1 | N40: =N36 -> 0 | Q40: 100 | R40: =VLOOKUP(L40,'道具表|itemBase'!$A$5:$C$1112,3,FALSE) -> 1
...

Sheet 属性枚举|GameAttr$Enum
A1: 编号 | B1: 属性内部名 | C1: 属性外部名 | D1: 说明
A2: int | B2: string | C2: string | D2: string
A3: id | B3: name | C3: note | D3: note2
A4: server/client | B4: server/client | C4: server/client | D4: server/client
A5: 1 | B5: HP | C5: 生命 | D5: 生命为0就会被消灭
A6: 2 | B6: SP | C6: 护盾 | D6: 抵抗生命伤害
A7: 3 | B7: attack | C7: 攻击力 | D7: 提高造成的伤害
A8: 4 | B8: def | C8: 防御力 | D8: 降低受到的伤害
A9: 5 | B9: block | C9: 格挡率 | D9: 有概率让攻击导致的伤害为0
A10: 6 | B10: aoeHurtCorrect | C10: AOE伤害百分比
A11: 7 | B11: aoeCriticalProbability | C11: AOE暴击率 | D11: AOE暴击概率
A12: 8 | B12: aoeCriticalDam | C12: AOE暴击伤害倍率 | D12: AOE暴击伤害
A13: 9 | B13: hitHurtCorrect | C13: 命中伤害百分比
A14: 10 | B14: hitCriticalProbability | C14: 命中暴击率 | D14: 命中暴击概率
A15: 11 | B15: hitCriticalDam | C15: 命中暴击伤害倍率 | D15: 命中暴击伤害
A16: 12 | B16: damageCorrect | C16: 子弹伤害修正
A17: 13 | B17: monMove | C17: 怪物移动 | D17: 每秒经过多少坐标距离
A18: 14 | B18: heroMove | C18: 英雄移动速度 | D18: 每秒经过多少个格子
A19: 15 | B19: maxHP | C19: 生命最大值
A20: 16 | B20: maxSP | C20: 最大护盾值
A21: 17 | B21: ammoCost | C21: 激活需求 | D21: 需要多少抵达点数，才能激活效果
A22: 18 | B22: load | C22: 装填效率 | D22: 每次抵达，提供多少抵达点数
A23: 19 | B23: cd | C23: 冷却时间 | D23: 激活后，需要多少毫秒才能再次使用
A24: 101 | B24: atkMul | C24: 百分比修改攻击
A25: 102 | B25: maxHPMul | C25: 百分比修改最大HP
A26: 103 | B26: moveMul | C26: 百分比修改移动速度
A27: 104 | B27: maxSPMul | C27: 百分比修改最大护盾

Sheet 装备升级|wapenUp（废弃）
A1: ='M1'!A7 -> 等级 | B1: ='M1'!B7 -> 期望DPS | D1: 保底元宝 | E1: 对标关卡 | AB1: 等级 | AC1: 消耗的道具 | AD1: 类型1的价格 | AE1: 类型1的攻击 | AF1: 类型2的价格 | AG1: 类型2的攻击 | AH1: 类型3的价格 | AI1: 类型3的攻击 | AJ1: 类型4的价格 | AK1: 类型4的攻击 | AL1: 类型5的价格 | AM1: 类型5的攻击 | AN1: 类型6的价格 | AO1: 类型6的攻击 | AP1: 类型7的价格 | AQ1: 类型7的攻击 | AR1: 类型8的价格 | AS1: 类型8的攻击
A2: ='M1'!A8 -> 1 | B2: ='M1'!B8 -> 10 | D2: ='关卡表|pass'!AA55 -> 29500 | E2: 50 | L2: 攻击放大 | N2: 攻击放大 | P2: 攻击放大 | R2: 攻击放大 | T2: 攻击放大 | V2: 攻击放大 | X2: 攻击放大 | Z2: 攻击放大 | AB2: int | AC2: int | AD2: int | AE2: int | AF2: int | AG2: int | AH2: int | AI2: int | AJ2: int | AK2: int | AL2: int | AM2: int | AN2: int | AO2: int | AP2: int | AQ2: int | AR2: int | AS2: int
A3: ='M1'!A9 -> 2 | B3: ='M1'!B9 -> 20 | D3: 元宝倍率 | E3: 总消耗 | I3: 消耗权重 | J3: 攻击间隔 | K3: ='装备大类|wapenTable'!Q5 -> 1 | L3: 1 | M3: ='装备大类|wapenTable'!Q6 -> 1 | N3: 1.1 | O3: ='装备大类|wapenTable'!Q7 -> 2 | P3: 1.2 | Q3: ='装备大类|wapenTable'!Q8 -> 2 | R3: 1.3 | S3: ='装备大类|wapenTable'!Q9 -> 2 | T3: 1.4 | U3: ='装备大类|wapenTable'!Q10 -> 2 | V3: 1.5 | W3: ='装备大类|wapenTable'!Q11 -> 3 | X3: 1.6 | Y3: ='装备大类|wapenTable'!Q12 -> 4 | Z3: 1.7 | AB3: id | AC3: item | AD3: cost1 | AE3: atk1 | AF3: cost2 | AG3: atk2 | AH3: cost3 | AI3: atk3 | AJ3: cost4 | AK3: atk4 | AL3: cost5 | AM3: atk5 | AN3: cost6 | AO3: atk6 | AP3: cost7 | AQ3: atk7 | AR3: cost8 | AS3: atk8
A4: ='M1'!A10 -> 3 | B4: ='M1'!B10 -> 30 | D4: 75 | E4: =D4*D2 -> 2212500 | I4: =SUM(K5:K34)+SUM(M5:M34)+SUM(O5:O34)+SUM(Q5:Q34)+SUM(S5:S34)+SUM(U5:U34)+SUM(W5:W34)+SUM(Y5:Y34) -> 7672.0744 | J4: 类型ID | K4: 1 | L4: 攻击设置 | M4: 2 | O4: 3 | Q4: 4 | S4: 5 | U4: 6 | W4: 7 | Y4: 8 | AB4: server/client | AC4: server/client | AD4: server/client | AE4: server/client | AF4: server/client | AG4: server/client | AH4: server/client | AI4: server/client | AJ4: server/client | AK4: server/client | AL4: server/client | AM4: server/client | AN4: server/client | AO4: server/client | AP4: server/client | AQ4: server/client | AR4: server/client | AS4: server/client
A5: ='M1'!A11 -> 4 | B5: ='M1'!B11 -> 40 | I5: 升级总消耗 | J5: 消耗 | K5: 1 | L5: =$B$2/(1/K3)*L3 -> 10 | M5: =K5*1.2 -> 1.2 | N5: =$B$2/(1/M3)*N3 -> 11 | O5: =M5*1.2 -> 1.44 | P5: =$B$2/(1/O3)*P3 -> 24 | Q5: =O5*1.2 -> 1.728 | R5: =$B$2/(1/Q3)*R3 -> 26 | S5: =Q5*1.2 -> 2.0736 | T5: =$B$2/(1/S3)*T3 -> 28 | U5: =S5*1.2 -> 2.48832 | V5: =$B$2/(1/U3)*V3 -> 30 | W5: =U5*1.2 -> 2.985984 | X5: =$B$2/(1/W3)*X3 -> 48 | Y5: =W5*1.2 -> 3.5831808 | Z5: =$B$2/(1/Y3)*Z3 -> 68 | AB5: 1 | AC5: 1 | AD5: =INT($E$4*(K5/$I$4)) -> 288 | AE5: =L5 -> 10 | AF5: =INT($E$4*(M5/$I$4)) -> 346 | AG5: =N5 -> 11 | AH5: =INT($E$4*(O5/$I$4)) -> 415 | AI5: =P5 -> 24 | AJ5: =INT($E$4*(Q5/$I$4)) -> 498 | AK5: =R5 -> 26 | AL5: =INT($E$4*(S5/$I$4)) -> 597 | AM5: =T5 -> 28 | AN5: =INT($E$4*(U5/$I$4)) -> 717 | AO5: =V5 -> 30 | AP5: =INT($E$4*(W5/$I$4)) -> 861 | AQ5: =X5 -> 48 | AR5: =INT($E$4*(Y5/$I$4)) -> 1033 | AS5: =Z5 -> 68
I6: =AD5+AF5+AH5+AJ5+AL5+AN5+AP5+AR5 -> 4755 | J6: 2 | K6: 2 | L6: 1.1 | M6: =K6*1.2 -> 2.4 | N6: 1.1 | O6: =M6*1.2 -> 2.88 | P6: 1.1 | Q6: =O6*1.2 -> 3.456 | R6: 1.1 | S6: =Q6*1.2 -> 4.1472 | T6: 1.1 | U6: =S6*1.2 -> 4.97664 | V6: 1.1 | W6: =U6*1.2 -> 5.971968 | X6: 1.1 | Y6: =W6*1.2 -> 7.1663616 | Z6: 1.1 | AB6: 2 | AC6: 1 | AD6: =INT($E$4*(K6/$I$4)) -> 576 | AE6: =AE5+L$5*(L6-1) -> 11 | AF6: =INT($E$4*(M6/$I$4)) -> 692 | AG6: =AG5+N$5*(N6-1) -> 12.1 | AH6: =INT($E$4*(O6/$I$4)) -> 830 | AI6: =AI5+P$5*(P6-1) -> 26.4 | AJ6: =INT($E$4*(Q6/$I$4)) -> 996 | AK6: =AK5+R$5*(R6-1) -> 28.6 | AL6: =INT($E$4*(S6/$I$4)) -> 1195 | AM6: =AM5+T$5*(T6-1) -> 30.8 | AN6: =INT($E$4*(U6/$I$4)) -> 1435 | AO6: =AO5+V$5*(V6-1) -> 33 | AP6: =INT($E$4*(W6/$I$4)) -> 1722 | AQ6: =AQ5+X$5*(X6-1) -> 52.8 | AR6: =INT($E$4*(Y6/$I$4)) -> 2066 | AS6: =AS5+Z$5*(Z6-1) -> 74.8
I7: =AD6+AF6+AH6+AJ6+AL6+AN6+AP6+AR6+I6 -> 14267 | J7: =AB7 -> 3 | K7: 3 | L7: 1.1 | M7: =K7*1.2 -> 3.6 | N7: 1.1 | O7: =M7*1.2 -> 4.32 | P7: 1.1 | Q7: =O7*1.2 -> 5.184 | R7: 1.1 | S7: =Q7*1.2 -> 6.2208 | T7: 1.1 | U7: =S7*1.2 -> 7.46496 | V7: 1.1 | W7: =U7*1.2 -> 8.957952 | X7: 1.1 | Y7: =W7*1.2 -> 10.749542 | Z7: 1.1 | AB7: 3 | AC7: 1 | AD7: =INT($E$4*(K7/$I$4)) -> 865 | AE7: =AE6+L$5*(L7-1) -> 12 | AF7: =INT($E$4*(M7/$I$4)) -> 1038 | AG7: =AG6+N$5*(N7-1) -> 13.2 | AH7: =INT($E$4*(O7/$I$4)) -> 1245 | AI7: =AI6+P$5*(P7-1) -> 28.8 | AJ7: =INT($E$4*(Q7/$I$4)) -> 1494 | AK7: =AK6+R$5*(R7-1) -> 31.2 | AL7: =INT($E$4*(S7/$I$4)) -> 1793 | AM7: =AM6+T$5*(T7-1) -> 33.6 | AN7: =INT($E$4*(U7/$I$4)) -> 2152 | AO7: =AO6+V$5*(V7-1) -> 36 | AP7: =INT($E$4*(W7/$I$4)) -> 2583 | AQ7: =AQ6+X$5*(X7-1) -> 57.6 | AR7: =INT($E$4*(Y7/$I$4)) -> 3099 | AS7: =AS6+Z$5*(Z7-1) -> 81.6
I8: =AD7+AF7+AH7+AJ7+AL7+AN7+AP7+AR7+I7 -> 28536 | J8: =AB8 -> 4 | K8: 4 | L8: 1.1 | M8: =K8*1.2 -> 4.8 | N8: 1.1 | O8: =M8*1.2 -> 5.76 | P8: 1.1 | Q8: =O8*1.2 -> 6.912 | R8: 1.1 | S8: =Q8*1.2 -> 8.2944 | T8: 1.1 | U8: =S8*1.2 -> 9.95328 | V8: 1.1 | W8: =U8*1.2 -> 11.943936 | X8: 1.1 | Y8: =W8*1.2 -> 14.332723 | Z8: 1.1 | AB8: 4 | AC8: 1 | AD8: =INT($E$4*(K8/$I$4)) -> 1153 | AE8: =AE7+L$5*(L8-1) -> 13 | AF8: =INT($E$4*(M8/$I$4)) -> 1384 | AG8: =AG7+N$5*(N8-1) -> 14.3 | AH8: =INT($E$4*(O8/$I$4)) -> 1661 | AI8: =AI7+P$5*(P8-1) -> 31.2 | AJ8: =INT($E$4*(Q8/$I$4)) -> 1993 | AK8: =AK7+R$5*(R8-1) -> 33.8 | AL8: =INT($E$4*(S8/$I$4)) -> 2391 | AM8: =AM7+T$5*(T8-1) -> 36.4 | AN8: =INT($E$4*(U8/$I$4)) -> 2870 | AO8: =AO7+V$5*(V8-1) -> 39 | AP8: =INT($E$4*(W8/$I$4)) -> 3444 | AQ8: =AQ7+X$5*(X8-1) -> 62.4 | AR8: =INT($E$4*(Y8/$I$4)) -> 4133 | AS8: =AS7+Z$5*(Z8-1) -> 88.4
A9: 大类ID | B9: 系数 | I9: =AD8+AF8+AH8+AJ8+AL8+AN8+AP8+AR8+I8 -> 47565 | J9: =AB9 -> 5 | K9: 5 | L9: 1.1 | M9: =K9*1.2 -> 6 | N9: 1.1 | O9: =M9*1.2 -> 7.2 | P9: 1.1 | Q9: =O9*1.2 -> 8.64 | R9: 1.1 | S9: =Q9*1.2 -> 10.368 | T9: 1.1 | U9: =S9*1.2 -> 12.4416 | V9: 1.1 | W9: =U9*1.2 -> 14.92992 | X9: 1.1 | Y9: =W9*1.2 -> 17.915904 | Z9: 1.1 | AB9: 5 | AC9: 1 | AD9: =INT($E$4*(K9/$I$4)) -> 1441 | AE9: =AE8+L$5*(L9-1) -> 14 | AF9: =INT($E$4*(M9/$I$4)) -> 1730 | AG9: =AG8+N$5*(N9-1) -> 15.4 | AH9: =INT($E$4*(O9/$I$4)) -> 2076 | AI9: =AI8+P$5*(P9-1) -> 33.6 | AJ9: =INT($E$4*(Q9/$I$4)) -> 2491 | AK9: =AK8+R$5*(R9-1) -> 36.4 | AL9: =INT($E$4*(S9/$I$4)) -> 2989 | AM9: =AM8+T$5*(T9-1) -> 39.2 | AN9: =INT($E$4*(U9/$I$4)) -> 3587 | AO9: =AO8+V$5*(V9-1) -> 42 | AP9: =INT($E$4*(W9/$I$4)) -> 4305 | AQ9: =AQ8+X$5*(X9-1) -> 67.2 | AR9: =INT($E$4*(Y9/$I$4)) -> 5166 | AS9: =AS8+Z$5*(Z9-1) -> 95.2
A10: 1 | B10: =L3 -> 1 | I10: =AD9+AF9+AH9+AJ9+AL9+AN9+AP9+AR9+I9 -> 71350 | J10: =AB10 -> 6 | K10: 6 | L10: 1.1 | M10: =K10*1.2 -> 7.2 | N10: 1.1 | O10: =M10*1.2 -> 8.64 | P10: 1.1 | Q10: =O10*1.2 -> 10.368 | R10: 1.1 | S10: =Q10*1.2 -> 12.4416 | T10: 1.1 | U10: =S10*1.2 -> 14.92992 | V10: 1.1 | W10: =U10*1.2 -> 17.915904 | X10: 1.1 | Y10: =W10*1.2 -> 21.499085 | Z10: 1.1 | AB10: 6 | AC10: 1 | AD10: =INT($E$4*(K10/$I$4)) -> 1730 | AE10: =AE9+L$5*(L10-1) -> 15 | AF10: =INT($E$4*(M10/$I$4)) -> 2076 | AG10: =AG9+N$5*(N10-1) -> 16.5 | AH10: =INT($E$4*(O10/$I$4)) -> 2491 | AI10: =AI9+P$5*(P10-1) -> 36 | AJ10: =INT($E$4*(Q10/$I$4)) -> 2989 | AK10: =AK9+R$5*(R10-1) -> 39 | AL10: =INT($E$4*(S10/$I$4)) -> 3587 | AM10: =AM9+T$5*(T10-1) -> 42 | AN10: =INT($E$4*(U10/$I$4)) -> 4305 | AO10: =AO9+V$5*(V10-1) -> 45 | AP10: =INT($E$4*(W10/$I$4)) -> 5166 | AQ10: =AQ9+X$5*(X10-1) -> 72 | AR10: =INT($E$4*(Y10/$I$4)) -> 6199 | AS10: =AS9+Z$5*(Z10-1) -> 102
A11: 2 | B11: =N3 -> 1.1 | I11: =AD10+AF10+AH10+AJ10+AL10+AN10+AP10+AR10+I10 -> 99893 | J11: =AB11 -> 7 | K11: 7 | L11: 1.1 | M11: =K11*1.2 -> 8.4 | N11: 1.1 | O11: =M11*1.2 -> 10.08 | P11: 1.1 | Q11: =O11*1.2 -> 12.096 | R11: 1.1 | S11: =Q11*1.2 -> 14.5152 | T11: 1.1 | U11: =S11*1.2 -> 17.41824 | V11: 1.1 | W11: =U11*1.2 -> 20.901888 | X11: 1.1 | Y11: =W11*1.2 -> 25.082266 | Z11: 1.1 | AB11: 7 | AC11: 1 | AD11: =INT($E$4*(K11/$I$4)) -> 2018 | AE11: =AE10+L$5*(L11-1) -> 16 | AF11: =INT($E$4*(M11/$I$4)) -> 2422 | AG11: =AG10+N$5*(N11-1) -> 17.6 | AH11: =INT($E$4*(O11/$I$4)) -> 2906 | AI11: =AI10+P$5*(P11-1) -> 38.4 | AJ11: =INT($E$4*(Q11/$I$4)) -> 3488 | AK11: =AK10+R$5*(R11-1) -> 41.6 | AL11: =INT($E$4*(S11/$I$4)) -> 4185 | AM11: =AM10+T$5*(T11-1) -> 44.8 | AN11: =INT($E$4*(U11/$I$4)) -> 5023 | AO11: =AO10+V$5*(V11-1) -> 48 | AP11: =INT($E$4*(W11/$I$4)) -> 6027 | AQ11: =AQ10+X$5*(X11-1) -> 76.8 | AR11: =INT($E$4*(Y11/$I$4)) -> 7233 | AS11: =AS10+Z$5*(Z11-1) -> 108.8
A12: 3 | B12: =P3 -> 1.2 | I12: =AD11+AF11+AH11+AJ11+AL11+AN11+AP11+AR11+I11 -> 133195 | J12: =AB12 -> 8 | K12: 8 | L12: 1.1 | M12: =K12*1.2 -> 9.6 | N12: 1.1 | O12: =M12*1.2 -> 11.52 | P12: 1.1 | Q12: =O12*1.2 -> 13.824 | R12: 1.1 | S12: =Q12*1.2 -> 16.5888 | T12: 1.1 | U12: =S12*1.2 -> 19.90656 | V12: 1.1 | W12: =U12*1.2 -> 23.887872 | X12: 1.1 | Y12: =W12*1.2 -> 28.665446 | Z12: 1.1 | AB12: 8 | AC12: 1 | AD12: =INT($E$4*(K12/$I$4)) -> 2307 | AE12: =AE11+L$5*(L12-1) -> 17 | AF12: =INT($E$4*(M12/$I$4)) -> 2768 | AG12: =AG11+N$5*(N12-1) -> 18.7 | AH12: =INT($E$4*(O12/$I$4)) -> 3322 | AI12: =AI11+P$5*(P12-1) -> 40.8 | AJ12: =INT($E$4*(Q12/$I$4)) -> 3986 | AK12: =AK11+R$5*(R12-1) -> 44.2 | AL12: =INT($E$4*(S12/$I$4)) -> 4783 | AM12: =AM11+T$5*(T12-1) -> 47.6 | AN12: =INT($E$4*(U12/$I$4)) -> 5740 | AO12: =AO11+V$5*(V12-1) -> 51 | AP12: =INT($E$4*(W12/$I$4)) -> 6888 | AQ12: =AQ11+X$5*(X12-1) -> 81.6 | AR12: =INT($E$4*(Y12/$I$4)) -> 8266 | AS12: =AS11+Z$5*(Z12-1) -> 115.6
A13: 4 | B13: =R3 -> 1.3 | I13: =AD12+AF12+AH12+AJ12+AL12+AN12+AP12+AR12+I12 -> 171255 | J13: =AB13 -> 9 | K13: 9 | L13: 1.1 | M13: =K13*1.2 -> 10.8 | N13: 1.1 | O13: =M13*1.2 -> 12.96 | P13: 1.1 | Q13: =O13*1.2 -> 15.552 | R13: 1.1 | S13: =Q13*1.2 -> 18.6624 | T13: 1.1 | U13: =S13*1.2 -> 22.39488 | V13: 1.1 | W13: =U13*1.2 -> 26.873856 | X13: 1.1 | Y13: =W13*1.2 -> 32.248627 | Z13: 1.1 | AB13: 9 | AC13: 1 | AD13: =INT($E$4*(K13/$I$4)) -> 2595 | AE13: =AE12+L$5*(L13-1) -> 18 | AF13: =INT($E$4*(M13/$I$4)) -> 3114 | AG13: =AG12+N$5*(N13-1) -> 19.8 | AH13: =INT($E$4*(O13/$I$4)) -> 3737 | AI13: =AI12+P$5*(P13-1) -> 43.2 | AJ13: =INT($E$4*(Q13/$I$4)) -> 4484 | AK13: =AK12+R$5*(R13-1) -> 46.8 | AL13: =INT($E$4*(S13/$I$4)) -> 5381 | AM13: =AM12+T$5*(T13-1) -> 50.4 | AN13: =INT($E$4*(U13/$I$4)) -> 6458 | AO13: =AO12+V$5*(V13-1) -> 54 | AP13: =INT($E$4*(W13/$I$4)) -> 7749 | AQ13: =AQ12+X$5*(X13-1) -> 86.4 | AR13: =INT($E$4*(Y13/$I$4)) -> 9299 | AS13: =AS12+Z$5*(Z13-1) -> 122.4
A14: 5 | B14: =T3 -> 1.4 | I14: =AD13+AF13+AH13+AJ13+AL13+AN13+AP13+AR13+I13 -> 214072 | J14: =AB14 -> 10 | K14: 10 | L14: 1.1 | M14: =K14*1.2 -> 12 | N14: 1.1 | O14: =M14*1.2 -> 14.4 | P14: 1.1 | Q14: =O14*1.2 -> 17.28 | R14: 1.1 | S14: =Q14*1.2 -> 20.736 | T14: 1.1 | U14: =S14*1.2 -> 24.8832 | V14: 1.1 | W14: =U14*1.2 -> 29.85984 | X14: 1.1 | Y14: =W14*1.2 -> 35.831808 | Z14: 1.1 | AB14: 10 | AC14: 1 | AD14: =INT($E$4*(K14/$I$4)) -> 2883 | AE14: =AE13+L$5*(L14-1) -> 19 | AF14: =INT($E$4*(M14/$I$4)) -> 3460 | AG14: =AG13+N$5*(N14-1) -> 20.9 | AH14: =INT($E$4*(O14/$I$4)) -> 4152 | AI14: =AI13+P$5*(P14-1) -> 45.6 | AJ14: =INT($E$4*(Q14/$I$4)) -> 4983 | AK14: =AK13+R$5*(R14-1) -> 49.4 | AL14: =INT($E$4*(S14/$I$4)) -> 5979 | AM14: =AM13+T$5*(T14-1) -> 53.2 | AN14: =INT($E$4*(U14/$I$4)) -> 7175 | AO14: =AO13+V$5*(V14-1) -> 57 | AP14: =INT($E$4*(W14/$I$4)) -> 8611 | AQ14: =AQ13+X$5*(X14-1) -> 91.2 | AR14: =INT($E$4*(Y14/$I$4)) -> 10333 | AS14: =AS13+Z$5*(Z14-1) -> 129.2
A15: 6 | B15: =V3 -> 1.5 | I15: =AD14+AF14+AH14+AJ14+AL14+AN14+AP14+AR14+I14 -> 261648 | J15: =AB15 -> 11 | K15: 11 | L15: 1.1 | M15: =K15*1.2 -> 13.2 | N15: 1.1 | O15: =M15*1.2 -> 15.84 | P15: 1.1 | Q15: =O15*1.2 -> 19.008 | R15: 1.1 | S15: =Q15*1.2 -> 22.8096 | T15: 1.1 | U15: =S15*1.2 -> 27.37152 | V15: 1.1 | W15: =U15*1.2 -> 32.845824 | X15: 1.1 | Y15: =W15*1.2 -> 39.414989 | Z15: 1.1 | AB15: 11 | AC15: 1 | AD15: =INT($E$4*(K15/$I$4)) -> 3172 | AE15: =AE14+L$5*(L15-1) -> 20 | AF15: =INT($E$4*(M15/$I$4)) -> 3806 | AG15: =AG14+N$5*(N15-1) -> 22 | AH15: =INT($E$4*(O15/$I$4)) -> 4567 | AI15: =AI14+P$5*(P15-1) -> 48 | AJ15: =INT($E$4*(Q15/$I$4)) -> 5481 | AK15: =AK14+R$5*(R15-1) -> 52 | AL15: =INT($E$4*(S15/$I$4)) -> 6577 | AM15: =AM14+T$5*(T15-1) -> 56 | AN15: =INT($E$4*(U15/$I$4)) -> 7893 | AO15: =AO14+V$5*(V15-1) -> 60 | AP15: =INT($E$4*(W15/$I$4)) -> 9472 | AQ15: =AQ14+X$5*(X15-1) -> 96 | AR15: =INT($E$4*(Y15/$I$4)) -> 11366 | AS15: =AS14+Z$5*(Z15-1) -> 136
A16: 7 | B16: =X3 -> 1.6 | I16: =AD15+AF15+AH15+AJ15+AL15+AN15+AP15+AR15+I15 -> 313982 | J16: =AB16 -> 12 | K16: 12 | L16: 1.1 | M16: =K16*1.2 -> 14.4 | N16: 1.1 | O16: =M16*1.2 -> 17.28 | P16: 1.1 | Q16: =O16*1.2 -> 20.736 | R16: 1.1 | S16: =Q16*1.2 -> 24.8832 | T16: 1.1 | U16: =S16*1.2 -> 29.85984 | V16: 1.1 | W16: =U16*1.2 -> 35.831808 | X16: 1.1 | Y16: =W16*1.2 -> 42.99817 | Z16: 1.1 | AB16: 12 | AC16: 1 | AD16: =INT($E$4*(K16/$I$4)) -> 3460 | AE16: =AE15+L$5*(L16-1) -> 21 | AF16: =INT($E$4*(M16/$I$4)) -> 4152 | AG16: =AG15+N$5*(N16-1) -> 23.1 | AH16: =INT($E$4*(O16/$I$4)) -> 4983 | AI16: =AI15+P$5*(P16-1) -> 50.4 | AJ16: =INT($E$4*(Q16/$I$4)) -> 5979 | AK16: =AK15+R$5*(R16-1) -> 54.6 | AL16: =INT($E$4*(S16/$I$4)) -> 7175 | AM16: =AM15+T$5*(T16-1) -> 58.8 | AN16: =INT($E$4*(U16/$I$4)) -> 8611 | AO16: =AO15+V$5*(V16-1) -> 63 | AP16: =INT($E$4*(W16/$I$4)) -> 10333 | AQ16: =AQ15+X$5*(X16-1) -> 100.8 | AR16: =INT($E$4*(Y16/$I$4)) -> 12399 | AS16: =AS15+Z$5*(Z16-1) -> 142.8
A17: 8 | B17: =Z3 -> 1.7 | I17: =AD16+AF16+AH16+AJ16+AL16+AN16+AP16+AR16+I16 -> 371074 | J17: =AB17 -> 13 | K17: 13 | L17: 1.1 | M17: =K17*1.2 -> 15.6 | N17: 1.1 | O17: =M17*1.2 -> 18.72 | P17: 1.1 | Q17: =O17*1.2 -> 22.464 | R17: 1.1 | S17: =Q17*1.2 -> 26.9568 | T17: 1.1 | U17: =S17*1.2 -> 32.34816 | V17: 1.1 | W17: =U17*1.2 -> 38.817792 | X17: 1.1 | Y17: =W17*1.2 -> 46.58135 | Z17: 1.1 | AB17: 13 | AC17: 1 | AD17: =INT($E$4*(K17/$I$4)) -> 3748 | AE17: =AE16+L$5*(L17-1) -> 22 | AF17: =INT($E$4*(M17/$I$4)) -> 4498 | AG17: =AG16+N$5*(N17-1) -> 24.2 | AH17: =INT($E$4*(O17/$I$4)) -> 5398 | AI17: =AI16+P$5*(P17-1) -> 52.8 | AJ17: =INT($E$4*(Q17/$I$4)) -> 6478 | AK17: =AK16+R$5*(R17-1) -> 57.2 | AL17: =INT($E$4*(S17/$I$4)) -> 7773 | AM17: =AM16+T$5*(T17-1) -> 61.6 | AN17: =INT($E$4*(U17/$I$4)) -> 9328 | AO17: =AO16+V$5*(V17-1) -> 66 | AP17: =INT($E$4*(W17/$I$4)) -> 11194 | AQ17: =AQ16+X$5*(X17-1) -> 105.6 | AR17: =INT($E$4*(Y17/$I$4)) -> 13433 | AS17: =AS16+Z$5*(Z17-1) -> 149.6
I18: =AD17+AF17+AH17+AJ17+AL17+AN17+AP17+AR17+I17 -> 432924 | J18: =AB18 -> 14 | K18: 14 | L18: 1.1 | M18: =K18*1.2 -> 16.8 | N18: 1.1 | O18: =M18*1.2 -> 20.16 | P18: 1.1 | Q18: =O18*1.2 -> 24.192 | R18: 1.1 | S18: =Q18*1.2 -> 29.0304 | T18: 1.1 | U18: =S18*1.2 -> 34.83648 | V18: 1.1 | W18: =U18*1.2 -> 41.803776 | X18: 1.1 | Y18: =W18*1.2 -> 50.164531 | Z18: 1.1 | AB18: 14 | AC18: 1 | AD18: =INT($E$4*(K18/$I$4)) -> 4037 | AE18: =AE17+L$5*(L18-1) -> 23 | AF18: =INT($E$4*(M18/$I$4)) -> 4844 | AG18: =AG17+N$5*(N18-1) -> 25.3 | AH18: =INT($E$4*(O18/$I$4)) -> 5813 | AI18: =AI17+P$5*(P18-1) -> 55.2 | AJ18: =INT($E$4*(Q18/$I$4)) -> 6976 | AK18: =AK17+R$5*(R18-1) -> 59.8 | AL18: =INT($E$4*(S18/$I$4)) -> 8371 | AM18: =AM17+T$5*(T18-1) -> 64.4 | AN18: =INT($E$4*(U18/$I$4)) -> 10046 | AO18: =AO17+V$5*(V18-1) -> 69 | AP18: =INT($E$4*(W18/$I$4)) -> 12055 | AQ18: =AQ17+X$5*(X18-1) -> 110.4 | AR18: =INT($E$4*(Y18/$I$4)) -> 14466 | AS18: =AS17+Z$5*(Z18-1) -> 156.4
I19: =AD18+AF18+AH18+AJ18+AL18+AN18+AP18+AR18+I18 -> 499532 | J19: =AB19 -> 15 | K19: 15 | L19: 1.1 | M19: =K19*1.2 -> 18 | N19: 1.1 | O19: =M19*1.2 -> 21.6 | P19: 1.1 | Q19: =O19*1.2 -> 25.92 | R19: 1.1 | S19: =Q19*1.2 -> 31.104 | T19: 1.1 | U19: =S19*1.2 -> 37.3248 | V19: 1.1 | W19: =U19*1.2 -> 44.78976 | X19: 1.1 | Y19: =W19*1.2 -> 53.747712 | Z19: 1.1 | AB19: 15 | AC19: 1 | AD19: =INT($E$4*(K19/$I$4)) -> 4325 | AE19: =AE18+L$5*(L19-1) -> 24 | AF19: =INT($E$4*(M19/$I$4)) -> 5190 | AG19: =AG18+N$5*(N19-1) -> 26.4 | AH19: =INT($E$4*(O19/$I$4)) -> 6229 | AI19: =AI18+P$5*(P19-1) -> 57.6 | AJ19: =INT($E$4*(Q19/$I$4)) -> 7474 | AK19: =AK18+R$5*(R19-1) -> 62.4 | AL19: =INT($E$4*(S19/$I$4)) -> 8969 | AM19: =AM18+T$5*(T19-1) -> 67.2 | AN19: =INT($E$4*(U19/$I$4)) -> 10763 | AO19: =AO18+V$5*(V19-1) -> 72 | AP19: =INT($E$4*(W19/$I$4)) -> 12916 | AQ19: =AQ18+X$5*(X19-1) -> 115.2 | AR19: =INT($E$4*(Y19/$I$4)) -> 15499 | AS19: =AS18+Z$5*(Z19-1) -> 163.2
I20: =AD19+AF19+AH19+AJ19+AL19+AN19+AP19+AR19+I19 -> 570897 | J20: =AB20 -> 16 | K20: 16 | L20: 1.1 | M20: =K20*1.2 -> 19.2 | N20: 1.1 | O20: =M20*1.2 -> 23.04 | P20: 1.1 | Q20: =O20*1.2 -> 27.648 | R20: 1.1 | S20: =Q20*1.2 -> 33.1776 | T20: 1.1 | U20: =S20*1.2 -> 39.81312 | V20: 1.1 | W20: =U20*1.2 -> 47.775744 | X20: 1.1 | Y20: =W20*1.2 -> 57.330893 | Z20: 1.1 | AB20: 16 | AC20: 1 | AD20: =INT($E$4*(K20/$I$4)) -> 4614 | AE20: =AE19+L$5*(L20-1) -> 25 | AF20: =INT($E$4*(M20/$I$4)) -> 5536 | AG20: =AG19+N$5*(N20-1) -> 27.5 | AH20: =INT($E$4*(O20/$I$4)) -> 6644 | AI20: =AI19+P$5*(P20-1) -> 60 | AJ20: =INT($E$4*(Q20/$I$4)) -> 7973 | AK20: =AK19+R$5*(R20-1) -> 65 | AL20: =INT($E$4*(S20/$I$4)) -> 9567 | AM20: =AM19+T$5*(T20-1) -> 70 | AN20: =INT($E$4*(U20/$I$4)) -> 11481 | AO20: =AO19+V$5*(V20-1) -> 75 | AP20: =INT($E$4*(W20/$I$4)) -> 13777 | AQ20: =AQ19+X$5*(X20-1) -> 120 | AR20: =INT($E$4*(Y20/$I$4)) -> 16533 | AS20: =AS19+Z$5*(Z20-1) -> 170
I21: =AD20+AF20+AH20+AJ20+AL20+AN20+AP20+AR20+I20 -> 647022 | J21: =AB21 -> 17 | K21: 17 | L21: 1.1 | M21: =K21*1.2 -> 20.4 | N21: 1.1 | O21: =M21*1.2 -> 24.48 | P21: 1.1 | Q21: =O21*1.2 -> 29.376 | R21: 1.1 | S21: =Q21*1.2 -> 35.2512 | T21: 1.1 | U21: =S21*1.2 -> 42.30144 | V21: 1.1 | W21: =U21*1.2 -> 50.761728 | X21: 1.1 | Y21: =W21*1.2 -> 60.914074 | Z21: 1.1 | AB21: 17 | AC21: 1 | AD21: =INT($E$4*(K21/$I$4)) -> 4902 | AE21: =AE20+L$5*(L21-1) -> 26 | AF21: =INT($E$4*(M21/$I$4)) -> 5883 | AG21: =AG20+N$5*(N21-1) -> 28.6 | AH21: =INT($E$4*(O21/$I$4)) -> 7059 | AI21: =AI20+P$5*(P21-1) -> 62.4 | AJ21: =INT($E$4*(Q21/$I$4)) -> 8471 | AK21: =AK20+R$5*(R21-1) -> 67.6 | AL21: =INT($E$4*(S21/$I$4)) -> 10165 | AM21: =AM20+T$5*(T21-1) -> 72.8 | AN21: =INT($E$4*(U21/$I$4)) -> 12199 | AO21: =AO20+V$5*(V21-1) -> 78 | AP21: =INT($E$4*(W21/$I$4)) -> 14638 | AQ21: =AQ20+X$5*(X21-1) -> 124.8 | AR21: =INT($E$4*(Y21/$I$4)) -> 17566 | AS21: =AS20+Z$5*(Z21-1) -> 176.8
I22: =AD21+AF21+AH21+AJ21+AL21+AN21+AP21+AR21+I21 -> 727905 | J22: =AB22 -> 18 | K22: 18 | L22: 1.1 | M22: =K22*1.2 -> 21.6 | N22: 1.1 | O22: =M22*1.2 -> 25.92 | P22: 1.1 | Q22: =O22*1.2 -> 31.104 | R22: 1.1 | S22: =Q22*1.2 -> 37.3248 | T22: 1.1 | U22: =S22*1.2 -> 44.78976 | V22: 1.1 | W22: =U22*1.2 -> 53.747712 | X22: 1.1 | Y22: =W22*1.2 -> 64.497254 | Z22: 1.1 | AB22: 18 | AC22: 1 | AD22: =INT($E$4*(K22/$I$4)) -> 5190 | AE22: =AE21+L$5*(L22-1) -> 27 | AF22: =INT($E$4*(M22/$I$4)) -> 6229 | AG22: =AG21+N$5*(N22-1) -> 29.7 | AH22: =INT($E$4*(O22/$I$4)) -> 7474 | AI22: =AI21+P$5*(P22-1) -> 64.8 | AJ22: =INT($E$4*(Q22/$I$4)) -> 8969 | AK22: =AK21+R$5*(R22-1) -> 70.2 | AL22: =INT($E$4*(S22/$I$4)) -> 10763 | AM22: =AM21+T$5*(T22-1) -> 75.6 | AN22: =INT($E$4*(U22/$I$4)) -> 12916 | AO22: =AO21+V$5*(V22-1) -> 81 | AP22: =INT($E$4*(W22/$I$4)) -> 15499 | AQ22: =AQ21+X$5*(X22-1) -> 129.6 | AR22: =INT($E$4*(Y22/$I$4)) -> 18599 | AS22: =AS21+Z$5*(Z22-1) -> 183.6
I23: =AD22+AF22+AH22+AJ22+AL22+AN22+AP22+AR22+I22 -> 813544 | J23: =AB23 -> 19 | K23: 19 | L23: 1.1 | M23: =K23*1.2 -> 22.8 | N23: 1.1 | O23: =M23*1.2 -> 27.36 | P23: 1.1 | Q23: =O23*1.2 -> 32.832 | R23: 1.1 | S23: =Q23*1.2 -> 39.3984 | T23: 1.1 | U23: =S23*1.2 -> 47.27808 | V23: 1.1 | W23: =U23*1.2 -> 56.733696 | X23: 1.1 | Y23: =W23*1.2 -> 68.080435 | Z23: 1.1 | AB23: 19 | AC23: 1 | AD23: =INT($E$4*(K23/$I$4)) -> 5479 | AE23: =AE22+L$5*(L23-1) -> 28 | AF23: =INT($E$4*(M23/$I$4)) -> 6575 | AG23: =AG22+N$5*(N23-1) -> 30.8 | AH23: =INT($E$4*(O23/$I$4)) -> 7890 | AI23: =AI22+P$5*(P23-1) -> 67.2 | AJ23: =INT($E$4*(Q23/$I$4)) -> 9468 | AK23: =AK22+R$5*(R23-1) -> 72.8 | AL23: =INT($E$4*(S23/$I$4)) -> 11361 | AM23: =AM22+T$5*(T23-1) -> 78.4 | AN23: =INT($E$4*(U23/$I$4)) -> 13634 | AO23: =AO22+V$5*(V23-1) -> 84 | AP23: =INT($E$4*(W23/$I$4)) -> 16361 | AQ23: =AQ22+X$5*(X23-1) -> 134.4 | AR23: =INT($E$4*(Y23/$I$4)) -> 19633 | AS23: =AS22+Z$5*(Z23-1) -> 190.4
I24: =AD23+AF23+AH23+AJ23+AL23+AN23+AP23+AR23+I23 -> 903945 | J24: =AB24 -> 20 | K24: 20 | L24: 1.1 | M24: =K24*1.2 -> 24 | N24: 1.1 | O24: =M24*1.2 -> 28.8 | P24: 1.1 | Q24: =O24*1.2 -> 34.56 | R24: 1.1 | S24: =Q24*1.2 -> 41.472 | T24: 1.1 | U24: =S24*1.2 -> 49.7664 | V24: 1.1 | W24: =U24*1.2 -> 59.71968 | X24: 1.1 | Y24: =W24*1.2 -> 71.663616 | Z24: 1.1 | AB24: 20 | AC24: 1 | AD24: =INT($E$4*(K24/$I$4)) -> 5767 | AE24: =AE23+L$5*(L24-1) -> 29 | AF24: =INT($E$4*(M24/$I$4)) -> 6921 | AG24: =AG23+N$5*(N24-1) -> 31.9 | AH24: =INT($E$4*(O24/$I$4)) -> 8305 | AI24: =AI23+P$5*(P24-1) -> 69.6 | AJ24: =INT($E$4*(Q24/$I$4)) -> 9966 | AK24: =AK23+R$5*(R24-1) -> 75.4 | AL24: =INT($E$4*(S24/$I$4)) -> 11959 | AM24: =AM23+T$5*(T24-1) -> 81.2 | AN24: =INT($E$4*(U24/$I$4)) -> 14351 | AO24: =AO23+V$5*(V24-1) -> 87 | AP24: =INT($E$4*(W24/$I$4)) -> 17222 | AQ24: =AQ23+X$5*(X24-1) -> 139.2 | AR24: =INT($E$4*(Y24/$I$4)) -> 20666 | AS24: =AS23+Z$5*(Z24-1) -> 197.2
I25: =AD24+AF24+AH24+AJ24+AL24+AN24+AP24+AR24+I24 -> 999102 | J25: =AB25 -> 21 | K25: 21 | L25: 1.1 | M25: =K25*1.2 -> 25.2 | N25: 1.1 | O25: =M25*1.2 -> 30.24 | P25: 1.1 | Q25: =O25*1.2 -> 36.288 | R25: 1.1 | S25: =Q25*1.2 -> 43.5456 | T25: 1.1 | U25: =S25*1.2 -> 52.25472 | V25: 1.1 | W25: =U25*1.2 -> 62.705664 | X25: 1.1 | Y25: =W25*1.2 -> 75.246797 | Z25: 1.1 | AB25: 21 | AC25: 1 | AD25: =INT($E$4*(K25/$I$4)) -> 6056 | AE25: =AE24+L$5*(L25-1) -> 30 | AF25: =INT($E$4*(M25/$I$4)) -> 7267 | AG25: =AG24+N$5*(N25-1) -> 33 | AH25: =INT($E$4*(O25/$I$4)) -> 8720 | AI25: =AI24+P$5*(P25-1) -> 72 | AJ25: =INT($E$4*(Q25/$I$4)) -> 10464 | AK25: =AK24+R$5*(R25-1) -> 78 | AL25: =INT($E$4*(S25/$I$4)) -> 12557 | AM25: =AM24+T$5*(T25-1) -> 84 | AN25: =INT($E$4*(U25/$I$4)) -> 15069 | AO25: =AO24+V$5*(V25-1) -> 90 | AP25: =INT($E$4*(W25/$I$4)) -> 18083 | AQ25: =AQ24+X$5*(X25-1) -> 144 | AR25: =INT($E$4*(Y25/$I$4)) -> 21699 | AS25: =AS24+Z$5*(Z25-1) -> 204
I26: =AD25+AF25+AH25+AJ25+AL25+AN25+AP25+AR25+I25 -> 1099017 | J26: =AB26 -> 22 | K26: 22 | L26: 1.1 | M26: =K26*1.2 -> 26.4 | N26: 1.1 | O26: =M26*1.2 -> 31.68 | P26: 1.1 | Q26: =O26*1.2 -> 38.016 | R26: 1.1 | S26: =Q26*1.2 -> 45.6192 | T26: 1.1 | U26: =S26*1.2 -> 54.74304 | V26: 1.1 | W26: =U26*1.2 -> 65.691648 | X26: 1.1 | Y26: =W26*1.2 -> 78.829978 | Z26: 1.1 | AB26: 22 | AC26: 1 | AD26: =INT($E$4*(K26/$I$4)) -> 6344 | AE26: =AE25+L$5*(L26-1) -> 31 | AF26: =INT($E$4*(M26/$I$4)) -> 7613 | AG26: =AG25+N$5*(N26-1) -> 34.1 | AH26: =INT($E$4*(O26/$I$4)) -> 9135 | AI26: =AI25+P$5*(P26-1) -> 74.4 | AJ26: =INT($E$4*(Q26/$I$4)) -> 10963 | AK26: =AK25+R$5*(R26-1) -> 80.6 | AL26: =INT($E$4*(S26/$I$4)) -> 13155 | AM26: =AM25+T$5*(T26-1) -> 86.8 | AN26: =INT($E$4*(U26/$I$4)) -> 15786 | AO26: =AO25+V$5*(V26-1) -> 93 | AP26: =INT($E$4*(W26/$I$4)) -> 18944 | AQ26: =AQ25+X$5*(X26-1) -> 148.8 | AR26: =INT($E$4*(Y26/$I$4)) -> 22733 | AS26: =AS25+Z$5*(Z26-1) -> 210.8
I27: =AD26+AF26+AH26+AJ26+AL26+AN26+AP26+AR26+I26 -> 1203690 | J27: =AB27 -> 23 | K27: 23 | L27: 1.1 | M27: =K27*1.2 -> 27.6 | N27: 1.1 | O27: =M27*1.2 -> 33.12 | P27: 1.1 | Q27: =O27*1.2 -> 39.744 | R27: 1.1 | S27: =Q27*1.2 -> 47.6928 | T27: 1.1 | U27: =S27*1.2 -> 57.23136 | V27: 1.1 | W27: =U27*1.2 -> 68.677632 | X27: 1.1 | Y27: =W27*1.2 -> 82.413158 | Z27: 1.1 | AB27: 23 | AC27: 1 | AD27: =INT($E$4*(K27/$I$4)) -> 6632 | AE27: =AE26+L$5*(L27-1) -> 32 | AF27: =INT($E$4*(M27/$I$4)) -> 7959 | AG27: =AG26+N$5*(N27-1) -> 35.2 | AH27: =INT($E$4*(O27/$I$4)) -> 9551 | AI27: =AI26+P$5*(P27-1) -> 76.8 | AJ27: =INT($E$4*(Q27/$I$4)) -> 11461 | AK27: =AK26+R$5*(R27-1) -> 83.2 | AL27: =INT($E$4*(S27/$I$4)) -> 13753 | AM27: =AM26+T$5*(T27-1) -> 89.6 | AN27: =INT($E$4*(U27/$I$4)) -> 16504 | AO27: =AO26+V$5*(V27-1) -> 96 | AP27: =INT($E$4*(W27/$I$4)) -> 19805 | AQ27: =AQ26+X$5*(X27-1) -> 153.6 | AR27: =INT($E$4*(Y27/$I$4)) -> 23766 | AS27: =AS26+Z$5*(Z27-1) -> 217.6
I28: =AD27+AF27+AH27+AJ27+AL27+AN27+AP27+AR27+I27 -> 1313121 | J28: =AB28 -> 24 | K28: 24 | L28: 1.1 | M28: =K28*1.2 -> 28.8 | N28: 1.1 | O28: =M28*1.2 -> 34.56 | P28: 1.1 | Q28: =O28*1.2 -> 41.472 | R28: 1.1 | S28: =Q28*1.2 -> 49.7664 | T28: 1.1 | U28: =S28*1.2 -> 59.71968 | V28: 1.1 | W28: =U28*1.2 -> 71.663616 | X28: 1.1 | Y28: =W28*1.2 -> 85.996339 | Z28: 1.1 | AB28: 24 | AC28: 1 | AD28: =INT($E$4*(K28/$I$4)) -> 6921 | AE28: =AE27+L$5*(L28-1) -> 33 | AF28: =INT($E$4*(M28/$I$4)) -> 8305 | AG28: =AG27+N$5*(N28-1) -> 36.3 | AH28: =INT($E$4*(O28/$I$4)) -> 9966 | AI28: =AI27+P$5*(P28-1) -> 79.2 | AJ28: =INT($E$4*(Q28/$I$4)) -> 11959 | AK28: =AK27+R$5*(R28-1) -> 85.8 | AL28: =INT($E$4*(S28/$I$4)) -> 14351 | AM28: =AM27+T$5*(T28-1) -> 92.4 | AN28: =INT($E$4*(U28/$I$4)) -> 17222 | AO28: =AO27+V$5*(V28-1) -> 99 | AP28: =INT($E$4*(W28/$I$4)) -> 20666 | AQ28: =AQ27+X$5*(X28-1) -> 158.4 | AR28: =INT($E$4*(Y28/$I$4)) -> 24799 | AS28: =AS27+Z$5*(Z28-1) -> 224.4
I29: =AD28+AF28+AH28+AJ28+AL28+AN28+AP28+AR28+I28 -> 1427310 | J29: =AB29 -> 25 | K29: 25 | L29: 1.1 | M29: =K29*1.2 -> 30 | N29: 1.1 | O29: =M29*1.2 -> 36 | P29: 1.1 | Q29: =O29*1.2 -> 43.2 | R29: 1.1 | S29: =Q29*1.2 -> 51.84 | T29: 1.1 | U29: =S29*1.2 -> 62.208 | V29: 1.1 | W29: =U29*1.2 -> 74.6496 | X29: 1.1 | Y29: =W29*1.2 -> 89.57952 | Z29: 1.1 | AB29: 25 | AC29: 1 | AD29: =INT($E$4*(K29/$I$4)) -> 7209 | AE29: =AE28+L$5*(L29-1) -> 34 | AF29: =INT($E$4*(M29/$I$4)) -> 8651 | AG29: =AG28+N$5*(N29-1) -> 37.4 | AH29: =INT($E$4*(O29/$I$4)) -> 10381 | AI29: =AI28+P$5*(P29-1) -> 81.6 | AJ29: =INT($E$4*(Q29/$I$4)) -> 12458 | AK29: =AK28+R$5*(R29-1) -> 88.4 | AL29: =INT($E$4*(S29/$I$4)) -> 14949 | AM29: =AM28+T$5*(T29-1) -> 95.2 | AN29: =INT($E$4*(U29/$I$4)) -> 17939 | AO29: =AO28+V$5*(V29-1) -> 102 | AP29: =INT($E$4*(W29/$I$4)) -> 21527 | AQ29: =AQ28+X$5*(X29-1) -> 163.2 | AR29: =INT($E$4*(Y29/$I$4)) -> 25833 | AS29: =AS28+Z$5*(Z29-1) -> 231.2
... I34: =AD33+AF33+AH33+AJ33+AL33+AN33+AP33+AR33+I33 -> 2069626 | J34: =AB34 -> 30 | K34: 30 | L34: 1.1 | M34: =K34*1.2 -> 36 | N34: 1.1 | O34: =M34*1.2 -> 43.2 | P34: 1.1 | Q34: =O34*1.2 -> 51.84 | R34: 1.1 | S34: =Q34*1.2 -> 62.208 | T34: 1.1 | U34: =S34*1.2 -> 74.6496 | V34: 1.1 | W34: =U34*1.2 -> 89.57952 | X34: 1.1 | Y34: =W34*1.2 -> 107.49542 | Z34: 1.1 | AB34: 30 | AC34: 1 | AD34: =INT($E$4*(K34/$I$4)) -> 8651 | AE34: =AE33+L$5*(L34-1) -> 39 | AF34: =INT($E$4*(M34/$I$4)) -> 10381 | AG34: =AG33+N$5*(N34-1) -> 42.9 | AH34: =INT($E$4*(O34/$I$4)) -> 12458 | AI34: =AI33+P$5*(P34-1) -> 93.6 | AJ34: =INT($E$4*(Q34/$I$4)) -> 14949 | AK34: =AK33+R$5*(R34-1) -> 101.4 | AL34: =INT($E$4*(S34/$I$4)) -> 17939 | AM34: =AM33+T$5*(T34-1) -> 109.2 | AN34: =INT($E$4*(U34/$I$4)) -> 21527 | AO34: =AO33+V$5*(V34-1) -> 117 | AP34: =INT($E$4*(W34/$I$4)) -> 25833 | AQ34: =AQ33+X$5*(X34-1) -> 187.2 | AR34: =INT($E$4*(Y34/$I$4)) -> 30999 | AS34: =AS33+Z$5*(Z34-1) -> 265.2

Sheet 装备消耗|wapenCost
A1: ='M1'!A7 -> 等级 | B1: ='M1'!B7 -> 期望DPS | D1: 升级元宝总消耗 | I1: 装备总数 | AA1: 序号 | AB1: 装备消耗ID | AC1: 等级 | AD1: 碎片需求 | AE1: 元宝需求
A2: ='M1'!A8 -> 1 | B2: ='M1'!B8 -> 10 | D2: ='M1'!S14 -> 1382500 | I2: 17 | AA2: int | AB2: int | AC2: int | AD2: int | AE2: int
A3: ='M1'!A9 -> 2 | B3: ='M1'!B9 -> 20 | D3: 手动输入平均元宝总消耗 | I3: 平均元宝总消耗 | AA3: id | AB3: wapenCostId | AC3: lv | AD3: cost1 | AE3: cost2
A4: ='M1'!A10 -> 3 | B4: ='M1'!B10 -> 30 | D4: 50000 | I4: =D2/I2 -> 81323.529 | Y4: 元宝需求 | AA4: server/client | AB4: server/client | AC4: server/client | AD4: server/client | AE4: server/client
A5: ='M1'!A11 -> 4 | B5: ='M1'!B11 -> 40 | Y5: =INT(VLOOKUP(AC5,$H$10:$J$39,2,FALSE)/$I$8*VLOOKUP(AB5,$A$10:$C$39,3,FALSE)) -> 67 | AA5: 1 | AB5: 1 | AC5: 1 | AD5: =ROUNDUP(VLOOKUP(AC5,$H$10:$J$39,3,FALSE)/$J$8*VLOOKUP(AB5,$A$10:$D$39,4,FALSE),0) -> 1 | AE5: =10^(LEN(Y5)-1)*INT(Y5/(10^(LEN(Y5)-1))) -> 60
Y6: =INT(VLOOKUP(AC6,$H$10:$J$39,2,FALSE)/$I$8*VLOOKUP(AB6,$A$10:$C$39,3,FALSE)) -> 134 | AA6: =AA5+1 -> 2 | AB6: 1 | AC6: 2 | AD6: =ROUNDUP(VLOOKUP(AC6,$H$10:$J$39,3,FALSE)/$J$8*VLOOKUP(AB6,$A$10:$D$39,4,FALSE),0) -> 3 | AE6: =10^(LEN(Y6)-1)*INT(Y6/(10^(LEN(Y6)-1))) -> 100
Y7: =INT(VLOOKUP(AC7,$H$10:$J$39,2,FALSE)/$I$8*VLOOKUP(AB7,$A$10:$C$39,3,FALSE)) -> 201 | AA7: =AA6+1 -> 3 | AB7: 1 | AC7: 3 | AD7: =ROUNDUP(VLOOKUP(AC7,$H$10:$J$39,3,FALSE)/$J$8*VLOOKUP(AB7,$A$10:$D$39,4,FALSE),0) -> 4 | AE7: =10^(LEN(Y7)-1)*INT(Y7/(10^(LEN(Y7)-1))) -> 200
A8: 总权重 | H8: 总权重 | I8: =SUM(I10:I39) -> 670 | J8: =SUM(J10:J39) -> 488 | Y8: =INT(VLOOKUP(AC8,$H$10:$J$39,2,FALSE)/$I$8*VLOOKUP(AB8,$A$10:$C$39,3,FALSE)) -> 269 | AA8: =AA7+1 -> 4 | AB8: 1 | AC8: 4 | AD8: =ROUNDUP(VLOOKUP(AC8,$H$10:$J$39,3,FALSE)/$J$8*VLOOKUP(AB8,$A$10:$D$39,4,FALSE),0) -> 5 | AE8: =10^(LEN(Y8)-1)*INT(Y8/(10^(LEN(Y8)-1))) -> 200
A9: 装备消耗ID | C9: 元宝消耗 | D9: 碎片总消耗 | E9: 消耗系数 | F9: 升20元宝 | G9: 升20碎片 | H9: 等级 | I9: 等级间元宝权重 | J9: 等级间碎片权重 | Y9: =INT(VLOOKUP(AC9,$H$10:$J$39,2,FALSE)/$I$8*VLOOKUP(AB9,$A$10:$C$39,3,FALSE)) -> 336 | AA9: =AA8+1 -> 5 | AB9: 1 | AC9: 5 | AD9: =ROUNDUP(VLOOKUP(AC9,$H$10:$J$39,3,FALSE)/$J$8*VLOOKUP(AB9,$A$10:$D$39,4,FALSE),0) -> 6 | AE9: =10^(LEN(Y9)-1)*INT(Y9/(10^(LEN(Y9)-1))) -> 300
A10: 1 | C10: =VLOOKUP(A10,'M1'!$A$38:$H$54,8,FALSE) -> 45073.49 | D10: =VLOOKUP(A10,'M1'!$A$38:$G$54,5,FALSE)*E10 -> 700 | E10: 0.7 | F10: =SUM($I$10:$I$28)/$I$8*C10 -> 15809.358 | G10: =SUM($J$10:$J$28)/$J$8*D10 -> 162.09016 | H10: 1 | I10: 1 | J10: 0.5 | Y10: =INT(VLOOKUP(AC10,$H$10:$J$39,2,FALSE)/$I$8*VLOOKUP(AB10,$A$10:$C$39,3,FALSE)) -> 403 | AA10: =AA9+1 -> 6 | AB10: 1 | AC10: 6 | AD10: =ROUNDUP(VLOOKUP(AC10,$H$10:$J$39,3,FALSE)/$J$8*VLOOKUP(AB10,$A$10:$D$39,4,FALSE),0) -> 6 | AE10: =10^(LEN(Y10)-1)*INT(Y10/(10^(LEN(Y10)-1))) -> 400
A11: 2 | C11: =VLOOKUP(A11,'M1'!$A$38:$H$54,8,FALSE) -> 45812.4 | D11: =VLOOKUP(A11,'M1'!$A$38:$G$54,5,FALSE)*E11 -> 700 | E11: 0.7 | F11: =SUM($I$10:$I$28)/$I$8*C11 -> 16068.528 | G11: =SUM($J$10:$J$28)/$J$8*D11 -> 162.09016 | H11: 2 | I11: 2 | J11: 2 | Y11: =INT(VLOOKUP(AC11,$H$10:$J$39,2,FALSE)/$I$8*VLOOKUP(AB11,$A$10:$C$39,3,FALSE)) -> 470 | AA11: =AA10+1 -> 7 | AB11: 1 | AC11: 7 | AD11: =ROUNDUP(VLOOKUP(AC11,$H$10:$J$39,3,FALSE)/$J$8*VLOOKUP(AB11,$A$10:$D$39,4,FALSE),0) -> 7 | AE11: =10^(LEN(Y11)-1)*INT(Y11/(10^(LEN(Y11)-1))) -> 400
A12: 3 | C12: =VLOOKUP(A12,'M1'!$A$38:$H$54,8,FALSE) -> 46551.309 | D12: =VLOOKUP(A12,'M1'!$A$38:$G$54,5,FALSE)*E12 -> 700 | E12: 0.7 | F12: =SUM($I$10:$I$28)/$I$8*C12 -> 16327.698 | G12: =SUM($J$10:$J$28)/$J$8*D12 -> 162.09016 | H12: 3 | I12: 3 | J12: 2.5 | Y12: =INT(VLOOKUP(AC12,$H$10:$J$39,2,FALSE)/$I$8*VLOOKUP(AB12,$A$10:$C$39,3,FALSE)) -> 538 | AA12: =AA11+1 -> 8 | AB12: 1 | AC12: 8 | AD12: =ROUNDUP(VLOOKUP(AC12,$H$10:$J$39,3,FALSE)/$J$8*VLOOKUP(AB12,$A$10:$D$39,4,FALSE),0) -> 8 | AE12: =10^(LEN(Y12)-1)*INT(Y12/(10^(LEN(Y12)-1))) -> 500
A13: 4 | C13: =VLOOKUP(A13,'M1'!$A$38:$H$54,8,FALSE) -> 47290.219 | D13: =VLOOKUP(A13,'M1'!$A$38:$G$54,5,FALSE)*E13 -> 700 | E13: 0.7 | F13: =SUM($I$10:$I$28)/$I$8*C13 -> 16586.868 | G13: =SUM($J$10:$J$28)/$J$8*D13 -> 162.09016 | H13: 4 | I13: 4 | J13: 3 | Y13: =INT(VLOOKUP(AC13,$H$10:$J$39,2,FALSE)/$I$8*VLOOKUP(AB13,$A$10:$C$39,3,FALSE)) -> 605 | AA13: =AA12+1 -> 9 | AB13: 1 | AC13: 9 | AD13: =ROUNDUP(VLOOKUP(AC13,$H$10:$J$39,3,FALSE)/$J$8*VLOOKUP(AB13,$A$10:$D$39,4,FALSE),0) -> 8 | AE13: =10^(LEN(Y13)-1)*INT(Y13/(10^(LEN(Y13)-1))) -> 600
A14: 5 | C14: =VLOOKUP(A14,'M1'!$A$38:$H$54,8,FALSE) -> 66501.871 | D14: =VLOOKUP(A14,'M1'!$A$38:$G$54,5,FALSE)*E14 -> 560 | E14: 0.7 | F14: =SUM($I$10:$I$28)/$I$8*C14 -> 23325.283 | G14: =SUM($J$10:$J$28)/$J$8*D14 -> 129.67213 | H14: 5 | I14: 5 | J14: 3.5 | Y14: =INT(VLOOKUP(AC14,$H$10:$J$39,2,FALSE)/$I$8*VLOOKUP(AB14,$A$10:$C$39,3,FALSE)) -> 672 | AA14: =AA13+1 -> 10 | AB14: 1 | AC14: 10 | AD14: =ROUNDUP(VLOOKUP(AC14,$H$10:$J$39,3,FALSE)/$J$8*VLOOKUP(AB14,$A$10:$D$39,4,FALSE),0) -> 9 | AE14: =10^(LEN(Y14)-1)*INT(Y14/(10^(LEN(Y14)-1))) -> 600
A15: 6 | C15: =VLOOKUP(A15,'M1'!$A$38:$H$54,8,FALSE) -> 85713.522 | D15: =VLOOKUP(A15,'M1'!$A$38:$G$54,5,FALSE)*E15 -> 420 | E15: 0.7 | F15: =SUM($I$10:$I$28)/$I$8*C15 -> 30063.698 | G15: =SUM($J$10:$J$28)/$J$8*D15 -> 97.254098 | H15: 6 | I15: 6 | J15: 4 | Y15: =INT(VLOOKUP(AC15,$H$10:$J$39,2,FALSE)/$I$8*VLOOKUP(AB15,$A$10:$C$39,3,FALSE)) -> 807 | AA15: =AA14+1 -> 11 | AB15: 1 | AC15: 11 | AD15: =ROUNDUP(VLOOKUP(AC15,$H$10:$J$39,3,FALSE)/$J$8*VLOOKUP(AB15,$A$10:$D$39,4,FALSE),0) -> 10 | AE15: =10^(LEN(Y15)-1)*INT(Y15/(10^(LEN(Y15)-1))) -> 800
A16: 7 | C16: =VLOOKUP(A16,'M1'!$A$38:$H$54,8,FALSE) -> 86452.432 | D16: =VLOOKUP(A16,'M1'!$A$38:$G$54,5,FALSE)*E16 -> 420 | E16: 0.7 | F16: =SUM($I$10:$I$28)/$I$8*C16 -> 30322.868 | G16: =SUM($J$10:$J$28)/$J$8*D16 -> 97.254098 | H16: 7 | I16: 7 | J16: 4.5 | Y16: =INT(VLOOKUP(AC16,$H$10:$J$39,2,FALSE)/$I$8*VLOOKUP(AB16,$A$10:$C$39,3,FALSE)) -> 941 | AA16: =AA15+1 -> 12 | AB16: 1 | AC16: 12 | AD16: =ROUNDUP(VLOOKUP(AC16,$H$10:$J$39,3,FALSE)/$J$8*VLOOKUP(AB16,$A$10:$D$39,4,FALSE),0) -> 11 | AE16: =10^(LEN(Y16)-1)*INT(Y16/(10^(LEN(Y16)-1))) -> 900
A17: 8 | C17: =VLOOKUP(A17,'M1'!$A$38:$H$54,8,FALSE) -> 105664.08 | D17: =VLOOKUP(A17,'M1'!$A$38:$G$54,5,FALSE)*E17 -> 280 | E17: 0.7 | F17: =SUM($I$10:$I$28)/$I$8*C17 -> 37061.283 | G17: =SUM($J$10:$J$28)/$J$8*D17 -> 64.836066 | H17: 8 | I17: 8 | J17: 5 | Y17: =INT(VLOOKUP(AC17,$H$10:$J$39,2,FALSE)/$I$8*VLOOKUP(AB17,$A$10:$C$39,3,FALSE)) -> 1076 | AA17: =AA16+1 -> 13 | AB17: 1 | AC17: 13 | AD17: =ROUNDUP(VLOOKUP(AC17,$H$10:$J$39,3,FALSE)/$J$8*VLOOKUP(AB17,$A$10:$D$39,4,FALSE),0) -> 11 | AE17: =10^(LEN(Y17)-1)*INT(Y17/(10^(LEN(Y17)-1))) -> 1000
A18: 20 | C18: =VLOOKUP(A18,'M1'!$A$38:$H$54,8,FALSE) -> 69457.509 | D18: =VLOOKUP(A18,'M1'!$A$38:$G$54,5,FALSE)*E18 -> 560 | E18: 0.7 | F18: =SUM($I$10:$I$28)/$I$8*C18 -> 24361.962 | G18: =SUM($J$10:$J$28)/$J$8*D18 -> 129.67213 | H18: 9 | I18: 9 | J18: 5.5 | Y18: =INT(VLOOKUP(AC18,$H$10:$J$39,2,FALSE)/$I$8*VLOOKUP(AB18,$A$10:$C$39,3,FALSE)) -> 1210 | AA18: =AA17+1 -> 14 | AB18: 1 | AC18: 14 | AD18: =ROUNDUP(VLOOKUP(AC18,$H$10:$J$39,3,FALSE)/$J$8*VLOOKUP(AB18,$A$10:$D$39,4,FALSE),0) -> 12 | AE18: =10^(LEN(Y18)-1)*INT(Y18/(10^(LEN(Y18)-1))) -> 1000
A19: 21 | C19: =VLOOKUP(A19,'M1'!$A$38:$H$54,8,FALSE) -> 70196.419 | D19: =VLOOKUP(A19,'M1'!$A$38:$G$54,5,FALSE)*E19 -> 560 | E19: 0.7 | F19: =SUM($I$10:$I$28)/$I$8*C19 -> 24621.132 | G19: =SUM($J$10:$J$28)/$J$8*D19 -> 129.67213 | H19: 10 | I19: 10 | J19: 6 | Y19: =INT(VLOOKUP(AC19,$H$10:$J$39,2,FALSE)/$I$8*VLOOKUP(AB19,$A$10:$C$39,3,FALSE)) -> 1345 | AA19: =AA18+1 -> 15 | AB19: 1 | AC19: 15 | AD19: =ROUNDUP(VLOOKUP(AC19,$H$10:$J$39,3,FALSE)/$J$8*VLOOKUP(AB19,$A$10:$D$39,4,FALSE),0) -> 13 | AE19: =10^(LEN(Y19)-1)*INT(Y19/(10^(LEN(Y19)-1))) -> 1000
A20: 22 | C20: =VLOOKUP(A20,'M1'!$A$38:$H$54,8,FALSE) -> 70935.329 | D20: =VLOOKUP(A20,'M1'!$A$38:$G$54,5,FALSE)*E20 -> 560 | E20: 0.7 | F20: =SUM($I$10:$I$28)/$I$8*C20 -> 24880.302 | G20: =SUM($J$10:$J$28)/$J$8*D20 -> 129.67213 | H20: 11 | I20: 12 | J20: 6.5 | Y20: =INT(VLOOKUP(AC20,$H$10:$J$39,2,FALSE)/$I$8*VLOOKUP(AB20,$A$10:$C$39,3,FALSE)) -> 1480 | AA20: =AA19+1 -> 16 | AB20: 1 | AC20: 16 | AD20: =ROUNDUP(VLOOKUP(AC20,$H$10:$J$39,3,FALSE)/$J$8*VLOOKUP(AB20,$A$10:$D$39,4,FALSE),0) -> 13 | AE20: =10^(LEN(Y20)-1)*INT(Y20/(10^(LEN(Y20)-1))) -> 1000
A21: 23 | C21: =VLOOKUP(A21,'M1'!$A$38:$H$54,8,FALSE) -> 71674.238 | D21: =VLOOKUP(A21,'M1'!$A$38:$G$54,5,FALSE)*E21 -> 280 | E21: 0.7 | F21: =SUM($I$10:$I$28)/$I$8*C21 -> 25139.472 | G21: =SUM($J$10:$J$28)/$J$8*D21 -> 64.836066 | H21: 12 | I21: 14 | J21: 7 | Y21: =INT(VLOOKUP(AC21,$H$10:$J$39,2,FALSE)/$I$8*VLOOKUP(AB21,$A$10:$C$39,3,FALSE)) -> 1614 | AA21: =AA20+1 -> 17 | AB21: 1 | AC21: 17 | AD21: =ROUNDUP(VLOOKUP(AC21,$H$10:$J$39,3,FALSE)/$J$8*VLOOKUP(AB21,$A$10:$D$39,4,FALSE),0) -> 14 | AE21: =10^(LEN(Y21)-1)*INT(Y21/(10^(LEN(Y21)-1))) -> 1000
... A26: 28 | C26: =VLOOKUP(A26,'M1'!$A$38:$H$54,8,FALSE) -> 112314.27 | D26: =VLOOKUP(A26,'M1'!$A$38:$G$54,5,FALSE)*E26 -> 280 | E26: 0.7 | F26: =SUM($I$10:$I$28)/$I$8*C26 -> 39393.811 | G26: =SUM($J$10:$J$28)/$J$8*D26 -> 64.836066 | H26: 17 | I26: 24 | J26: 9.5 | Y26: =INT(VLOOKUP(AC26,$H$10:$J$39,2,FALSE)/$I$8*VLOOKUP(AB26,$A$10:$C$39,3,FALSE)) -> 2421 | AA26: =AA25+1 -> 22 | AB26: 1 | AC26: 22 | AD26: =ROUNDUP(VLOOKUP(AC26,$H$10:$J$39,3,FALSE)/$J$8*VLOOKUP(AB26,$A$10:$D$39,4,FALSE),0) -> 36 | AE26: =10^(LEN(Y26)-1)*INT(Y26/(10^(LEN(Y26)-1))) -> 2000
A27: 29 | C27: =VLOOKUP(A27,'M1'!$A$38:$H$56,8,FALSE) -> 72413.148 | D27: =VLOOKUP(A27,'M1'!$A$38:$G$56,5,FALSE)*E27 -> 700 | E27: 0.7 | F27: =SUM($I$10:$I$28)/$I$8*C27 -> 25398.641 | G27: =SUM($J$10:$J$28)/$J$8*D27 -> 162.09016 | H27: 18 | I27: 26 | J27: 10 | Y27: =INT(VLOOKUP(AC27,$H$10:$J$39,2,FALSE)/$I$8*VLOOKUP(AB27,$A$10:$C$39,3,FALSE)) -> 2623 | AA27: =AA26+1 -> 23 | AB27: 1 | AC27: 23 | AD27: =ROUNDUP(VLOOKUP(AC27,$H$10:$J$39,3,FALSE)/$J$8*VLOOKUP(AB27,$A$10:$D$39,4,FALSE),0) -> 44 | AE27: =10^(LEN(Y27)-1)*INT(Y27/(10^(LEN(Y27)-1))) -> 2000
